Workbook

Sheet Tabellen
A1: Team | B1: Spiele | C1: Siege | D1: Unentsch. | E1: Niederlagen | F1: Tore + | G1: Tore- | H1: Tordiff. | I1: Punkte | J1: Platzierung
A2: 1BHME | B2: =COUNTIF(Spiele!B:B,A2)+COUNTIF(Spiele!C:C,A2) -> 0 | C2: =SUMPRODUCT((Spiele!B$2:B$100=A2)*(Spiele!D$2:D$100>Spiele!E$2:E$100))+SUMPRODUCT((Spiele!C$2:C$100=A2)*(Spiele!E$2:E$100>Spiele!D$2:D$100)) -> 0 | D2: =SUMPRODUCT((Spiele!B$2:B$100=A2)*(Spiele!D$2:D$100=Spiele!E$2:E$100))+SUMPRODUCT((Spiele!C$2:C$100=A2)*(Spiele!D$2:D$100=Spiele!E$2:E$100)) -> 0 | E2: =B2-C2-D2 -> 0 | F2: =SUMIF(Spiele!B:B,A2,Spiele!D:D)+SUMIF(Spiele!C:C,A2,Spiele!E:E) -> 0 | G2: =SUMIF(Spiele!B:B,A2,Spiele!E:E)+SUMIF(Spiele!C:C,A2,Spiele!D:D) -> 0 | H2: =F2-G2 -> 0 | I2: =C2*3+D2 -> 0 | J2: =IF(B2=0,"",1+SUMPRODUCT(($B$2:$B$6>0)*(($I$2:$I$6>I2)*1+($I$2:$I$6=I2)*($H$2:$H$6>H2)+($I$2:$I$6=I2)*($H$2:$H$6=H2)*($F$2:$F$6>F2)+($I$2:$I$6=I2)*($H$2:$H$6=H2)*($F$2:$F$6=F2)*(ROW($A$2:$A$6)<ROW(A2))))) | K2: Gruppe A
A3: 3AHITN | B3: =COUNTIF(Spiele!B:B,A3)+COUNTIF(Spiele!C:C,A3) -> 0 | C3: =SUMPRODUCT((Spiele!B$2:B$100=A3)*(Spiele!D$2:D$100>Spiele!E$2:E$100))+SUMPRODUCT((Spiele!C$2:C$100=A3)*(Spiele!E$2:E$100>Spiele!D$2:D$100)) -> 0 | D3: =SUMPRODUCT((Spiele!B$2:B$100=A3)*(Spiele!D$2:D$100=Spiele!E$2:E$100))+SUMPRODUCT((Spiele!C$2:C$100=A3)*(Spiele!D$2:D$100=Spiele!E$2:E$100)) -> 0 | E3: =B3-C3-D3 -> 0 | F3: =SUMIF(Spiele!B:B,A3,Spiele!D:D)+SUMIF(Spiele!C:C,A3,Spiele!E:E) -> 0 | G3: =SUMIF(Spiele!B:B,A3,Spiele!E:E)+SUMIF(Spiele!C:C,A3,Spiele!D:D) -> 0 | H3: =F3-G3 -> 0 | I3: =C3*3+D3 -> 0 | J3: =IF(B3=0,"",1+SUMPRODUCT(($B$2:$B$6>0)*(($I$2:$I$6>I3)*1+($I$2:$I$6=I3)*($H$2:$H$6>H3)+($I$2:$I$6=I3)*($H$2:$H$6=H3)*($F$2:$F$6>F3)+($I$2:$I$6=I3)*($H$2:$H$6=H3)*($F$2:$F$6=F3)*(ROW($A$2:$A$6)<ROW(A3)))))
A4: 3AHMBZ | B4: =COUNTIF(Spiele!B:B,A4)+COUNTIF(Spiele!C:C,A4) -> 0 | C4: =SUMPRODUCT((Spiele!B$2:B$100=A4)*(Spiele!D$2:D$100>Spiele!E$2:E$100))+SUMPRODUCT((Spiele!C$2:C$100=A4)*(Spiele!E$2:E$100>Spiele!D$2:D$100)) -> 0 | D4: =SUMPRODUCT((Spiele!B$2:B$100=A4)*(Spiele!D$2:D$100=Spiele!E$2:E$100))+SUMPRODUCT((Spiele!C$2:C$100=A4)*(Spiele!D$2:D$100=Spiele!E$2:E$100)) -> 0 | E4: =B4-C4-D4 -> 0 | F4: =SUMIF(Spiele!B:B,A4,Spiele!D:D)+SUMIF(Spiele!C:C,A4,Spiele!E:E) -> 0 | G4: =SUMIF(Spiele!B:B,A4,Spiele!E:E)+SUMIF(Spiele!C:C,A4,Spiele!D:D) -> 0 | H4: =F4-G4 -> 0 | I4: =C4*3+D4 -> 0 | J4: =IF(B4=0,"",1+SUMPRODUCT(($B$2:$B$6>0)*(($I$2:$I$6>I4)*1+($I$2:$I$6=I4)*($H$2:$H$6>H4)+($I$2:$I$6=I4)*($H$2:$H$6=H4)*($F$2:$F$6>F4)+($I$2:$I$6=I4)*($H$2:$H$6=H4)*($F$2:$F$6=F4)*(ROW($A$2:$A$6)<ROW(A4)))))
A5: 4AHMBZ | B5: =COUNTIF(Spiele!B:B,A5)+COUNTIF(Spiele!C:C,A5) -> 0 | C5: =SUMPRODUCT((Spiele!B$2:B$100=A5)*(Spiele!D$2:D$100>Spiele!E$2:E$100))+SUMPRODUCT((Spiele!C$2:C$100=A5)*(Spiele!E$2:E$100>Spiele!D$2:D$100)) -> 0 | D5: =SUMPRODUCT((Spiele!B$2:B$100=A5)*(Spiele!D$2:D$100=Spiele!E$2:E$100))+SUMPRODUCT((Spiele!C$2:C$100=A5)*(Spiele!D$2:D$100=Spiele!E$2:E$100)) -> 0 | E5: =B5-C5-D5 -> 0 | F5: =SUMIF(Spiele!B:B,A5,Spiele!D:D)+SUMIF(Spiele!C:C,A5,Spiele!E:E) -> 0 | G5: =SUMIF(Spiele!B:B,A5,Spiele!E:E)+SUMIF(Spiele!C:C,A5,Spiele!D:D) -> 0 | H5: =F5-G5 -> 0 | I5: =C5*3+D5 -> 0 | J5: =IF(B5=0,"",1+SUMPRODUCT(($B$2:$B$6>0)*(($I$2:$I$6>I5)*1+($I$2:$I$6=I5)*($H$2:$H$6>H5)+($I$2:$I$6=I5)*($H$2:$H$6=H5)*($F$2:$F$6>F5)+($I$2:$I$6=I5)*($H$2:$H$6=H5)*($F$2:$F$6=F5)*(ROW($A$2:$A$6)<ROW(A5)))))
A6: 3BHMBZ | B6: =COUNTIF(Spiele!B:B,A6)+COUNTIF(Spiele!C:C,A6) -> 0 | C6: =SUMPRODUCT((Spiele!B$2:B$100=A6)*(Spiele!D$2:D$100>Spiele!E$2:E$100))+SUMPRODUCT((Spiele!C$2:C$100=A6)*(Spiele!E$2:E$100>Spiele!D$2:D$100)) -> 0 | D6: =SUMPRODUCT((Spiele!B$2:B$100=A6)*(Spiele!D$2:D$100=Spiele!E$2:E$100))+SUMPRODUCT((Spiele!C$2:C$100=A6)*(Spiele!D$2:D$100=Spiele!E$2:E$100)) -> 0 | E6: =B6-C6-D6 -> 0 | F6: =SUMIF(Spiele!B:B,A6,Spiele!D:D)+SUMIF(Spiele!C:C,A6,Spiele!E:E) -> 0 | G6: =SUMIF(Spiele!B:B,A6,Spiele!E:E)+SUMIF(Spiele!C:C,A6,Spiele!D:D) -> 0 | H6: =F6-G6 -> 0 | I6: =C6*3+D6 -> 0 | J6: =IF(B6=0,"",1+SUMPRODUCT(($B$2:$B$6>0)*(($I$2:$I$6>I6)*1+($I$2:$I$6=I6)*($H$2:$H$6>H6)+($I$2:$I$6=I6)*($H$2:$H$6=H6)*($F$2:$F$6>F6)+($I$2:$I$6=I6)*($H$2:$H$6=H6)*($F$2:$F$6=F6)*(ROW($A$2:$A$6)<ROW(A6)))))
A7: 2AHEL | B7: =COUNTIF(Spiele!B:B,A7)+COUNTIF(Spiele!C:C,A7) -> 0 | C7: =SUMPRODUCT((Spiele!B$2:B$100=A7)*(Spiele!D$2:D$100>Spiele!E$2:E$100))+SUMPRODUCT((Spiele!C$2:C$100=A7)*(Spiele!E$2:E$100>Spiele!D$2:D$100)) -> 0 | D7: =SUMPRODUCT((Spiele!B$2:B$100=A7)*(Spiele!D$2:D$100=Spiele!E$2:E$100))+SUMPRODUCT((Spiele!C$2:C$100=A7)*(Spiele!D$2:D$100=Spiele!E$2:E$100)) -> 0 | E7: =B7-C7-D7 -> 0 | F7: =SUMIF(Spiele!B:B,A7,Spiele!D:D)+SUMIF(Spiele!C:C,A7,Spiele!E:E) -> 0 | G7: =SUMIF(Spiele!B:B,A7,Spiele!E:E)+SUMIF(Spiele!C:C,A7,Spiele!D:D) -> 0 | H7: =F7-G7 -> 0 | I7: =C7*3+D7 -> 0 | J7: =IF(B7=0,"",1+SUMPRODUCT(($B$7:$B$11>0)*(($I$7:$I$11>I7)*1+($I$7:$I$11=I7)*($H$7:$H$11>H7)+($I$7:$I$11=I7)*($H$7:$H$11=H7)*($F$7:$F$11>F7)+($I$7:$I$11=I7)*($H$7:$H$11=H7)*($F$7:$F$11=F7)*(ROW($A$7:$A$11)<ROW(A7))))) | K7: Gruppe B
A8: 1AHEL | B8: =COUNTIF(Spiele!B:B,A8)+COUNTIF(Spiele!C:C,A8) -> 0 | C8: =SUMPRODUCT((Spiele!B$2:B$100=A8)*(Spiele!D$2:D$100>Spiele!E$2:E$100))+SUMPRODUCT((Spiele!C$2:C$100=A8)*(Spiele!E$2:E$100>Spiele!D$2:D$100)) -> 0 | D8: =SUMPRODUCT((Spiele!B$2:B$100=A8)*(Spiele!D$2:D$100=Spiele!E$2:E$100))+SUMPRODUCT((Spiele!C$2:C$100=A8)*(Spiele!D$2:D$100=Spiele!E$2:E$100)) -> 0 | E8: =B8-C8-D8 -> 0 | F8: =SUMIF(Spiele!B:B,A8,Spiele!D:D)+SUMIF(Spiele!C:C,A8,Spiele!E:E) -> 0 | G8: =SUMIF(Spiele!B:B,A8,Spiele!E:E)+SUMIF(Spiele!C:C,A8,Spiele!D:D) -> 0 | H8: =F8-G8 -> 0 | I8: =C8*3+D8 -> 0 | J8: =IF(B8=0,"",1+SUMPRODUCT(($B$7:$B$11>0)*(($I$7:$I$11>I8)*1+($I$7:$I$11=I8)*($H$7:$H$11>H8)+($I$7:$I$11=I8)*($H$7:$H$11=H8)*($F$7:$F$11>F8)+($I$7:$I$11=I8)*($H$7:$H$11=H8)*($F$7:$F$11=F8)*(ROW($A$7:$A$11)<ROW(A8)))))
A9: 2AHMBZ | B9: =COUNTIF(Spiele!B:B,A9)+COUNTIF(Spiele!C:C,A9) -> 0 | C9: =SUMPRODUCT((Spiele!B$2:B$100=A9)*(Spiele!D$2:D$100>Spiele!E$2:E$100))+SUMPRODUCT((Spiele!C$2:C$100=A9)*(Spiele!E$2:E$100>Spiele!D$2:D$100)) -> 0 | D9: =SUMPRODUCT((Spiele!B$2:B$100=A9)*(Spiele!D$2:D$100=Spiele!E$2:E$100))+SUMPRODUCT((Spiele!C$2:C$100=A9)*(Spiele!D$2:D$100=Spiele!E$2:E$100)) -> 0 | E9: =B9-C9-D9 -> 0 | F9: =SUMIF(Spiele!B:B,A9,Spiele!D:D)+SUMIF(Spiele!C:C,A9,Spiele!E:E) -> 0 | G9: =SUMIF(Spiele!B:B,A9,Spiele!E:E)+SUMIF(Spiele!C:C,A9,Spiele!D:D) -> 0 | H9: =F9-G9 -> 0 | I9: =C9*3+D9 -> 0 | J9: =IF(B9=0,"",1+SUMPRODUCT(($B$7:$B$11>0)*(($I$7:$I$11>I9)*1+($I$7:$I$11=I9)*($H$7:$H$11>H9)+($I$7:$I$11=I9)*($H$7:$H$11=H9)*($F$7:$F$11>F9)+($I$7:$I$11=I9)*($H$7:$H$11=H9)*($F$7:$F$11=F9)*(ROW($A$7:$A$11)<ROW(A9)))))
A10: 3AHEL | B10: =COUNTIF(Spiele!B:B,A10)+COUNTIF(Spiele!C:C,A10) -> 0 | C10: =SUMPRODUCT((Spiele!B$2:B$100=A10)*(Spiele!D$2:D$100>Spiele!E$2:E$100))+SUMPRODUCT((Spiele!C$2:C$100=A10)*(Spiele!E$2:E$100>Spiele!D$2:D$100)) -> 0 | D10: =SUMPRODUCT((Spiele!B$2:B$100=A10)*(Spiele!D$2:D$100=Spiele!E$2:E$100))+SUMPRODUCT((Spiele!C$2:C$100=A10)*(Spiele!D$2:D$100=Spiele!E$2:E$100)) -> 0 | E10: =B10-C10-D10 -> 0 | F10: =SUMIF(Spiele!B:B,A10,Spiele!D:D)+SUMIF(Spiele!C:C,A10,Spiele!E:E) -> 0 | G10: =SUMIF(Spiele!B:B,A10,Spiele!E:E)+SUMIF(Spiele!C:C,A10,Spiele!D:D) -> 0 | H10: =F10-G10 -> 0 | I10: =C10*3+D10 -> 0 | J10: =IF(B10=0,"",1+SUMPRODUCT(($B$7:$B$11>0)*(($I$7:$I$11>I10)*1+($I$7:$I$11=I10)*($H$7:$H$11>H10)+($I$7:$I$11=I10)*($H$7:$H$11=H10)*($F$7:$F$11>F10)+($I$7:$I$11=I10)*($H$7:$H$11=H10)*($F$7:$F$11=F10)*(ROW($A$7:$A$11)<ROW(A10)))))
A11: 2AHME | B11: =COUNTIF(Spiele!B:B,A11)+COUNTIF(Spiele!C:C,A11) -> 0 | C11: =SUMPRODUCT((Spiele!B$2:B$100=A11)*(Spiele!D$2:D$100>Spiele!E$2:E$100))+SUMPRODUCT((Spiele!C$2:C$100=A11)*(Spiele!E$2:E$100>Spiele!D$2:D$100)) -> 0 | D11: =SUMPRODUCT((Spiele!B$2:B$100=A11)*(Spiele!D$2:D$100=Spiele!E$2:E$100))+SUMPRODUCT((Spiele!C$2:C$100=A11)*(Spiele!D$2:D$100=Spiele!E$2:E$100)) -> 0 | E11: =B11-C11-D11 -> 0 | F11: =SUMIF(Spiele!B:B,A11,Spiele!D:D)+SUMIF(Spiele!C:C,A11,Spiele!E:E) -> 0 | G11: =SUMIF(Spiele!B:B,A11,Spiele!E:E)+SUMIF(Spiele!C:C,A11,Spiele!D:D) -> 0 | H11: =F11-G11 -> 0 | I11: =C11*3+D11 -> 0 | J11: =IF(B11=0,"",1+SUMPRODUCT(($B$7:$B$11>0)*(($I$7:$I$11>I11)*1+($I$7:$I$11=I11)*($H$7:$H$11>H11)+($I$7:$I$11=I11)*($H$7:$H$11=H11)*($F$7:$F$11>F11)+($I$7:$I$11=I11)*($H$7:$H$11=H11)*($F$7:$F$11=F11)*(ROW($A$7:$A$11)<ROW(A11)))))
A12: 1AHMBZ | B12: =COUNTIF(Spiele!B:B,A12)+COUNTIF(Spiele!C:C,A12) -> 0 | C12: =SUMPRODUCT((Spiele!B$2:B$100=A12)*(Spiele!D$2:D$100>Spiele!E$2:E$100))+SUMPRODUCT((Spiele!C$2:C$100=A12)*(Spiele!E$2:E$100>Spiele!D$2:D$100)) -> 0 | D12: =SUMPRODUCT((Spiele!B$2:B$100=A12)*(Spiele!D$2:D$100=Spiele!E$2:E$100))+SUMPRODUCT((Spiele!C$2:C$100=A12)*(Spiele!D$2:D$100=Spiele!E$2:E$100)) -> 0 | E12: =B12-C12-D12 -> 0 | F12: =SUMIF(Spiele!B:B,A12,Spiele!D:D)+SUMIF(Spiele!C:C,A12,Spiele!E:E) -> 0 | G12: =SUMIF(Spiele!B:B,A12,Spiele!E:E)+SUMIF(Spiele!C:C,A12,Spiele!D:D) -> 0 | H12: =F12-G12 -> 0 | I12: =C12*3+D12 -> 0 | J12: =IF(B12=0,"",1+SUMPRODUCT(($B$12:$B$16>0)*(($I$12:$I$16>I12)*1+($I$12:$I$16=I12)*($H$12:$H$16>H12)+($I$12:$I$16=I12)*($H$12:$H$16=H12)*($F$12:$F$16>F12)+($I$12:$I$16=I12)*($H$12:$H$16=H12)*($F$12:$F$16=F12)*(ROW($A$12:$A$16)<ROW(A12))))) | K12: Gruppe C
A13: 2AHITN | B13: =COUNTIF(Spiele!B:B,A13)+COUNTIF(Spiele!C:C,A13) -> 0 | C13: =SUMPRODUCT((Spiele!B$2:B$100=A13)*(Spiele!D$2:D$100>Spiele!E$2:E$100))+SUMPRODUCT((Spiele!C$2:C$100=A13)*(Spiele!E$2:E$100>Spiele!D$2:D$100)) -> 0 | D13: =SUMPRODUCT((Spiele!B$2:B$100=A13)*(Spiele!D$2:D$100=Spiele!E$2:E$100))+SUMPRODUCT((Spiele!C$2:C$100=A13)*(Spiele!D$2:D$100=Spiele!E$2:E$100)) -> 0 | E13: =B13-C13-D13 -> 0 | F13: =SUMIF(Spiele!B:B,A13,Spiele!D:D)+SUMIF(Spiele!C:C,A13,Spiele!E:E) -> 0 | G13: =SUMIF(Spiele!B:B,A13,Spiele!E:E)+SUMIF(Spiele!C:C,A13,Spiele!D:D) -> 0 | H13: =F13-G13 -> 0 | I13: =C13*3+D13 -> 0 | J13: =IF(B13=0,"",1+SUMPRODUCT(($B$12:$B$16>0)*(($I$12:$I$16>I13)*1+($I$12:$I$16=I13)*($H$12:$H$16>H13)+($I$12:$I$16=I13)*($H$12:$H$16=H13)*($F$12:$F$16>F13)+($I$12:$I$16=I13)*($H$12:$H$16=H13)*($F$12:$F$16=F13)*(ROW($A$12:$A$16)<ROW(A13)))))
A14: 1AHITN | B14: =COUNTIF(Spiele!B:B,A14)+COUNTIF(Spiele!C:C,A14) -> 0 | C14: =SUMPRODUCT((Spiele!B$2:B$100=A14)*(Spiele!D$2:D$100>Spiele!E$2:E$100))+SUMPRODUCT((Spiele!C$2:C$100=A14)*(Spiele!E$2:E$100>Spiele!D$2:D$100)) -> 0 | D14: =SUMPRODUCT((Spiele!B$2:B$100=A14)*(Spiele!D$2:D$100=Spiele!E$2:E$100))+SUMPRODUCT((Spiele!C$2:C$100=A14)*(Spiele!D$2:D$100=Spiele!E$2:E$100)) -> 0 | E14: =B14-C14-D14 -> 0 | F14: =SUMIF(Spiele!B:B,A14,Spiele!D:D)+SUMIF(Spiele!C:C,A14,Spiele!E:E) -> 0 | G14: =SUMIF(Spiele!B:B,A14,Spiele!E:E)+SUMIF(Spiele!C:C,A14,Spiele!D:D) -> 0 | H14: =F14-G14 -> 0 | I14: =C14*3+D14 -> 0 | J14: =IF(B14=0,"",1+SUMPRODUCT(($B$12:$B$16>0)*(($I$12:$I$16>I14)*1+($I$12:$I$16=I14)*($H$12:$H$16>H14)+($I$12:$I$16=I14)*($H$12:$H$16=H14)*($F$12:$F$16>F14)+($I$12:$I$16=I14)*($H$12:$H$16=H14)*($F$12:$F$16=F14)*(ROW($A$12:$A$16)<ROW(A14)))))
A15: 2BHME | B15: =COUNTIF(Spiele!B:B,A15)+COUNTIF(Spiele!C:C,A15) -> 0 | C15: =SUMPRODUCT((Spiele!B$2:B$100=A15)*(Spiele!D$2:D$100>Spiele!E$2:E$100))+SUMPRODUCT((Spiele!C$2:C$100=A15)*(Spiele!E$2:E$100>Spiele!D$2:D$100)) -> 0 | D15: =SUMPRODUCT((Spiele!B$2:B$100=A15)*(Spiele!D$2:D$100=Spiele!E$2:E$100))+SUMPRODUCT((Spiele!C$2:C$100=A15)*(Spiele!D$2:D$100=Spiele!E$2:E$100)) -> 0 | E15: =B15-C15-D15 -> 0 | F15: =SUMIF(Spiele!B:B,A15,Spiele!D:D)+SUMIF(Spiele!C:C,A15,Spiele!E:E) -> 0 | G15: =SUMIF(Spiele!B:B,A15,Spiele!E:E)+SUMIF(Spiele!C:C,A15,Spiele!D:D) -> 0 | H15: =F15-G15 -> 0 | I15: =C15*3+D15 -> 0 | J15: =IF(B15=0,"",1+SUMPRODUCT(($B$12:$B$16>0)*(($I$12:$I$16>I15)*1+($I$12:$I$16=I15)*($H$12:$H$16>H15)+($I$12:$I$16=I15)*($H$12:$H$16=H15)*($F$12:$F$16>F15)+($I$12:$I$16=I15)*($H$12:$H$16=H15)*($F$12:$F$16=F15)*(ROW($A$12:$A$16)<ROW(A15)))))
A16: 1AHME | B16: =COUNTIF(Spiele!B:B,A16)+COUNTIF(Spiele!C:C,A16) -> 0 | C16: =SUMPRODUCT((Spiele!B$2:B$100=A16)*(Spiele!D$2:D$100>Spiele!E$2:E$100))+SUMPRODUCT((Spiele!C$2:C$100=A16)*(Spiele!E$2:E$100>Spiele!D$2:D$100)) -> 0 | D16: =SUMPRODUCT((Spiele!B$2:B$100=A16)*(Spiele!D$2:D$100=Spiele!E$2:E$100))+SUMPRODUCT((Spiele!C$2:C$100=A16)*(Spiele!D$2:D$100=Spiele!E$2:E$100)) -> 0 | E16: =B16-C16-D16 -> 0 | F16: =SUMIF(Spiele!B:B,A16,Spiele!D:D)+SUMIF(Spiele!C:C,A16,Spiele!E:E) -> 0 | G16: =SUMIF(Spiele!B:B,A16,Spiele!E:E)+SUMIF(Spiele!C:C,A16,Spiele!D:D) -> 0 | H16: =F16-G16 -> 0 | I16: =C16*3+D16 -> 0 | J16: =IF(B16=0,"",1+SUMPRODUCT(($B$12:$B$16>0)*(($I$12:$I$16>I16)*1+($I$12:$I$16=I16)*($H$12:$H$16>H16)+($I$12:$I$16=I16)*($H$12:$H$16=H16)*($F$12:$F$16>F16)+($I$12:$I$16=I16)*($H$12:$H$16=H16)*($F$12:$F$16=F16)*(ROW($A$12:$A$16)<ROW(A16)))))
A17: 2AFMBZ | B17: =COUNTIF(Spiele!B:B,A17)+COUNTIF(Spiele!C:C,A17) -> 0 | C17: =SUMPRODUCT((Spiele!B$2:B$100=A17)*(Spiele!D$2:D$100>Spiele!E$2:E$100))+SUMPRODUCT((Spiele!C$2:C$100=A17)*(Spiele!E$2:E$100>Spiele!D$2:D$100)) -> 0 | D17: =SUMPRODUCT((Spiele!B$2:B$100=A17)*(Spiele!D$2:D$100=Spiele!E$2:E$100))+SUMPRODUCT((Spiele!C$2:C$100=A17)*(Spiele!D$2:D$100=Spiele!E$2:E$100)) -> 0 | E17: =B17-C17-D17 -> 0 | F17: =SUMIF(Spiele!B:B,A17,Spiele!D:D)+SUMIF(Spiele!C:C,A17,Spiele!E:E) -> 0 | G17: =SUMIF(Spiele!B:B,A17,Spiele!E:E)+SUMIF(Spiele!C:C,A17,Spiele!D:D) -> 0 | H17: =F17-G17 -> 0 | I17: =C17*3+D17 -> 0 | J17: =IF(B17=0,"",1+SUMPRODUCT(($B$17:$B$21>0)*(($I$17:$I$21>I17)*1+($I$17:$I$21=I17)*($H$17:$H$21>H17)+($I$17:$I$21=I17)*($H$17:$H$21=H17)*($F$17:$F$21>F17)+($I$17:$I$21=I17)*($H$17:$H$21=H17)*($F$17:$F$21=F17)*(ROW($A$17:$A$21)<ROW(A17))))) | K17: Gruppe D
A18: 4BHME | B18: =COUNTIF(Spiele!B:B,A18)+COUNTIF(Spiele!C:C,A18) -> 0 | C18: =SUMPRODUCT((Spiele!B$2:B$100=A18)*(Spiele!D$2:D$100>Spiele!E$2:E$100))+SUMPRODUCT((Spiele!C$2:C$100=A18)*(Spiele!E$2:E$100>Spiele!D$2:D$100)) -> 0 | D18: =SUMPRODUCT((Spiele!B$2:B$100=A18)*(Spiele!D$2:D$100=Spiele!E$2:E$100))+SUMPRODUCT((Spiele!C$2:C$100=A18)*(Spiele!D$2:D$100=Spiele!E$2:E$100)) -> 0 | E18: =B18-C18-D18 -> 0 | F18: =SUMIF(Spiele!B:B,A18,Spiele!D:D)+SUMIF(Spiele!C:C,A18,Spiele!E:E) -> 0 | G18: =SUMIF(Spiele!B:B,A18,Spiele!E:E)+SUMIF(Spiele!C:C,A18,Spiele!D:D) -> 0 | H18: =F18-G18 -> 0 | I18: =C18*3+D18 -> 0 | J18: =IF(B18=0,"",1+SUMPRODUCT(($B$17:$B$21>0)*(($I$17:$I$21>I18)*1+($I$17:$I$21=I18)*($H$17:$H$21>H18)+($I$17:$I$21=I18)*($H$17:$H$21=H18)*($F$17:$F$21>F18)+($I$17:$I$21=I18)*($H$17:$H$21=H18)*($F$17:$F$21=F18)*(ROW($A$17:$A$21)<ROW(A18)))))
A19: 3BHME | B19: =COUNTIF(Spiele!B:B,A19)+COUNTIF(Spiele!C:C,A19) -> 0 | C19: =SUMPRODUCT((Spiele!B$2:B$100=A19)*(Spiele!D$2:D$100>Spiele!E$2:E$100))+SUMPRODUCT((Spiele!C$2:C$100=A19)*(Spiele!E$2:E$100>Spiele!D$2:D$100)) -> 0 | D19: =SUMPRODUCT((Spiele!B$2:B$100=A19)*(Spiele!D$2:D$100=Spiele!E$2:E$100))+SUMPRODUCT((Spiele!C$2:C$100=A19)*(Spiele!D$2:D$100=Spiele!E$2:E$100)) -> 0 | E19: =B19-C19-D19 -> 0 | F19: =SUMIF(Spiele!B:B,A19,Spiele!D:D)+SUMIF(Spiele!C:C,A19,Spiele!E:E) -> 0 | G19: =SUMIF(Spiele!B:B,A19,Spiele!E:E)+SUMIF(Spiele!C:C,A19,Spiele!D:D) -> 0 | H19: =F19-G19 -> 0 | I19: =C19*3+D19 -> 0 | J19: =IF(B19=0,"",1+SUMPRODUCT(($B$17:$B$21>0)*(($I$17:$I$21>I19)*1+($I$17:$I$21=I19)*($H$17:$H$21>H19)+($I$17:$I$21=I19)*($H$17:$H$21=H19)*($F$17:$F$21>F19)+($I$17:$I$21=I19)*($H$17:$H$21=H19)*($F$17:$F$21=F19)*(ROW($A$17:$A$21)<ROW(A19)))))
A20: 4AHEL | B20: =COUNTIF(Spiele!B:B,A20)+COUNTIF(Spiele!C:C,A20) -> 0 | C20: =SUMPRODUCT((Spiele!B$2:B$100=A20)*(Spiele!D$2:D$100>Spiele!E$2:E$100))+SUMPRODUCT((Spiele!C$2:C$100=A20)*(Spiele!E$2:E$100>Spiele!D$2:D$100)) -> 0 | D20: =SUMPRODUCT((Spiele!B$2:B$100=A20)*(Spiele!D$2:D$100=Spiele!E$2:E$100))+SUMPRODUCT((Spiele!C$2:C$100=A20)*(Spiele!D$2:D$100=Spiele!E$2:E$100)) -> 0 | E20: =B20-C20-D20 -> 0 | F20: =SUMIF(Spiele!B:B,A20,Spiele!D:D)+SUMIF(Spiele!C:C,A20,Spiele!E:E) -> 0 | G20: =SUMIF(Spiele!B:B,A20,Spiele!E:E)+SUMIF(Spiele!C:C,A20,Spiele!D:D) -> 0 | H20: =F20-G20 -> 0 | I20: =C20*3+D20 -> 0 | J20: =IF(B20=0,"",1+SUMPRODUCT(($B$17:$B$21>0)*(($I$17:$I$21>I20)*1+($I$17:$I$21=I20)*($H$17:$H$21>H20)+($I$17:$I$21=I20)*($H$17:$H$21=H20)*($F$17:$F$21>F20)+($I$17:$I$21=I20)*($H$17:$H$21=H20)*($F$17:$F$21=F20)*(ROW($A$17:$A$21)<ROW(A20)))))
A21: 4AHITN | B21: =COUNTIF(Spiele!B:B,A21)+COUNTIF(Spiele!C:C,A21) -> 0 | C21: =SUMPRODUCT((Spiele!B$2:B$100=A21)*(Spiele!D$2:D$100>Spiele!E$2:E$100))+SUMPRODUCT((Spiele!C$2:C$100=A21)*(Spiele!E$2:E$100>Spiele!D$2:D$100)) -> 0 | D21: =SUMPRODUCT((Spiele!B$2:B$100=A21)*(Spiele!D$2:D$100=Spiele!E$2:E$100))+SUMPRODUCT((Spiele!C$2:C$100=A21)*(Spiele!D$2:D$100=Spiele!E$2:E$100)) -> 0 | E21: =B21-C21-D21 -> 0 | F21: =SUMIF(Spiele!B:B,A21,Spiele!D:D)+SUMIF(Spiele!C:C,A21,Spiele!E:E) -> 0 | G21: =SUMIF(Spiele!B:B,A21,Spiele!E:E)+SUMIF(Spiele!C:C,A21,Spiele!D:D) -> 0 | H21: =F21-G21 -> 0 | I21: =C21*3+D21 -> 0 | J21: =IF(B21=0,"",1+SUMPRODUCT(($B$17:$B$21>0)*(($I$17:$I$21>I21)*1+($I$17:$I$21=I21)*($H$17:$H$21>H21)+($I$17:$I$21=I21)*($H$17:$H$21=H21)*($F$17:$F$21>F21)+($I$17:$I$21=I21)*($H$17:$H$21=H21)*($F$17:$F$21=F21)*(ROW($A$17:$A$21)<ROW(A21)))))

Sheet Gruppenphase
D4: Spiele Gruppenphase
C5: Platz 1 | D5: Zeit | E5: Gruppe A | G5: Tore | J5: Zeit | K5: Gruppe B | M5: Tore
D6: 0.34722222 | E6: 1BHME | F6: 3AHITN | J6: 0.35555556 | K6: 2AHEL | L6: 1AHEL
D7: 0.36388889 | E7: 3AHMBZ | F7: 3BHMBZ | J7: 0.37222222 | K7: 2AHMBZ | L7: 3AHEL
D8: 0.38055556 | E8: 4AHMBZ | F8: 1BHME | J8: 0.38888889 | K8: 2AHME | L8: 2AHEL
D9: 0.39722222 | E9: 3AHITN | F9: 3AHMBZ | J9: 0.40555556 | K9: 1AHEL | L9: 2AHMBZ
D10: 0.41388889 | E10: 3BHMBZ | F10: 4AHMBZ | J10: 0.42222222 | K10: 3AHEL | L10: 2AHME
D11: 0.43055556 | E11: 1BHME | F11: 3AHMBZ | J11: 0.43888889 | K11: 2AHEL | L11: 2AHMBZ
D12: 0.44722222 | E12: 3AHITN | F12: 3BHMBZ | J12: 0.45555556 | K12: 1AHEL | L12: 3AHEL
D13: 0.46388889 | E13: 3AHMBZ | F13: 4AHMBZ | J13: 0.47222222 | K13: 2AHMBZ | L13: 2AHME
D14: 0.48055556 | E14: 1BHME | F14: 3BHMBZ | J14: 0.48888889 | K14: 2AHEL | L14: 3AHEL
D15: 0.49722222 | E15: 3AHITN | F15: 4AHMBZ | J15: 0.50555556 | K15: 1AHEL | L15: 2AHME
E16: Strandseite | F16: Laufbahnseite | K16: Strandseite | L16: Laufbahnseite
C17: Platz 2 | D17: Zeit | E17: Gruppe C | G17: Tore | J17: Zeit | K17: Gruppe D | M17: Tore
D18: 0.34722222 | E18: 1AHMBZ | F18: 2AHITN | J18: 0.35555556 | K18: 2AFMBZ | L18: 4BHME
D19: 0.36388889 | E19: 1AHITN | F19: 2BHME | J19: 0.37222222 | K19: 3BHME | L19: 4AHEL
D20: 0.38055556 | E20: 1AHME | F20: 2AHITN | J20: 0.38888889 | K20: 4BHME | L20: 4AHITN
D21: 0.39722222 | E21: 1AHMBZ | F21: 1AHITN | J21: 0.40555556 | K21: 2AFMBZ | L21: 3BHME
D22: 0.41388889 | E22: 2BHME | F22: 1AHME | J22: 0.42222222 | K22: 4AHEL | L22: 4AHITN
D23: 0.43055556 | E23: 2AHITN | F23: 1AHITN | J23: 0.43888889 | K23: 3BHME | L23: 4BHME
D24: 0.44722222 | E24: 1AHMBZ | F24: 2BHME | J24: 0.45555556 | K24: 2AFMBZ | L24: 4AHEL
D25: 0.46388889 | E25: 1AHITN | F25: 1AHME | J25: 0.47222222 | K25: 3BHME | L25: 4AHITN
D26: 0.48055556 | E26: 2AHITN | F26: 2BHME | J26: 0.48888889 | K26: 4BHME | L26: 4AHEL
D27: 0.49722222 | E27: 1AHMBZ | F27: 1AHME | J27: 0.50555556 | K27: 2AFMBZ | L27: 4AHITN
E28: Strandseite | F28: Laufbahnseite | K28: Strandseite | L28: Laufbahnseite

Sheet Kreuzspiele
B2: Kreuzspiele
B3: Platz 1 | H3: Platz 2
B4: Zeit | C4: Spiel | E4: Tore | H4: Zeit | I4: Spiel | K4: Tore
B5: 0.51736111 | H5: 0.51736111
B6: 0.52708333 | H6: 0.52708333
C7: Strandseite | D7: Laufbahnseite | I7: Strandseite | J7: Laufbahnseite
B9: Halbfinale
B10: Platz 1 | H10: Platz 2
B11: Zeit | C11: Spiel | E11: Tore | H11: Zeit | I11: Spiel | K11: Tore
B12: 0.53819444 | H12: 0.53819444
C13: Strandseite | D13: Laufbahnseite | I13: Strandseite | J13: Laufbahnseite
B15: Kleines Finale | H15: Finale
B16: Zeit | C16: Spiel | E16: Tore | H16: Zeit | I16: Spiel | K16: Tore
B17: 0.54861111 | H17: 0.55902778
C18: Strandseite | D18: Laufbahnseite | I18: Strandseite | J18: Laufbahnseite

Sheet Spiele
A1: Spiel | B1: Team A | C1: Team B | D1: Tore A | E1: Tore B
A2: 1 | B2: =IF(AND(Gruppenphase!G6<>"",Gruppenphase!H6<>""),Gruppenphase!E6,"") | C2: =IF(AND(Gruppenphase!G6<>"",Gruppenphase!H6<>""),Gruppenphase!F6,"") | D2: =IF(AND(Gruppenphase!G6<>"",Gruppenphase!H6<>""),Gruppenphase!G6,"") | E2: =IF(AND(Gruppenphase!G6<>"",Gruppenphase!H6<>""),Gruppenphase!H6,"")
A3: 2 | B3: =IF(AND(Gruppenphase!G7<>"",Gruppenphase!H7<>""),Gruppenphase!E7,"") | C3: =IF(AND(Gruppenphase!G7<>"",Gruppenphase!H7<>""),Gruppenphase!F7,"") | D3: =IF(AND(Gruppenphase!G7<>"",Gruppenphase!H7<>""),Gruppenphase!G7,"") | E3: =IF(AND(Gruppenphase!G7<>"",Gruppenphase!H7<>""),Gruppenphase!H7,"")
A4: 3 | B4: =IF(AND(Gruppenphase!G8<>"",Gruppenphase!H8<>""),Gruppenphase!E8,"") | C4: =IF(AND(Gruppenphase!G8<>"",Gruppenphase!H8<>""),Gruppenphase!F8,"") | D4: =IF(AND(Gruppenphase!G8<>"",Gruppenphase!H8<>""),Gruppenphase!G8,"") | E4: =IF(AND(Gruppenphase!G8<>"",Gruppenphase!H8<>""),Gruppenphase!H8,"")
A5: 4 | B5: =IF(AND(Gruppenphase!G9<>"",Gruppenphase!H9<>""),Gruppenphase!E9,"") | C5: =IF(AND(Gruppenphase!G9<>"",Gruppenphase!H9<>""),Gruppenphase!F9,"") | D5: =IF(AND(Gruppenphase!G9<>"",Gruppenphase!H9<>""),Gruppenphase!G9,"") | E5: =IF(AND(Gruppenphase!G9<>"",Gruppenphase!H9<>""),Gruppenphase!H9,"")
A6: 5 | B6: =IF(AND(Gruppenphase!G10<>"",Gruppenphase!H10<>""),Gruppenphase!E10,"") | C6: =IF(AND(Gruppenphase!G10<>"",Gruppenphase!H10<>""),Gruppenphase!F10,"") | D6: =IF(AND(Gruppenphase!G10<>"",Gruppenphase!H10<>""),Gruppenphase!G10,"") | E6: =IF(AND(Gruppenphase!G10<>"",Gruppenphase!H10<>""),Gruppenphase!H10,"")
A7: 6 | B7: =IF(AND(Gruppenphase!G11<>"",Gruppenphase!H11<>""),Gruppenphase!E11,"") | C7: =IF(AND(Gruppenphase!G11<>"",Gruppenphase!H11<>""),Gruppenphase!F11,"") | D7: =IF(AND(Gruppenphase!G11<>"",Gruppenphase!H11<>""),Gruppenphase!G11,"") | E7: =IF(AND(Gruppenphase!G11<>"",Gruppenphase!H11<>""),Gruppenphase!H11,"")
A8: 7 | B8: =IF(AND(Gruppenphase!G12<>"",Gruppenphase!H12<>""),Gruppenphase!E12,"") | C8: =IF(AND(Gruppenphase!G12<>"",Gruppenphase!H12<>""),Gruppenphase!F12,"") | D8: =IF(AND(Gruppenphase!G12<>"",Gruppenphase!H12<>""),Gruppenphase!G12,"") | E8: =IF(AND(Gruppenphase!G12<>"",Gruppenphase!H12<>""),Gruppenphase!H12,"")
A9: 8 | B9: =IF(AND(Gruppenphase!G13<>"",Gruppenphase!H13<>""),Gruppenphase!E13,"") | C9: =IF(AND(Gruppenphase!G13<>"",Gruppenphase!H13<>""),Gruppenphase!F13,"") | D9: =IF(AND(Gruppenphase!G13<>"",Gruppenphase!H13<>""),Gruppenphase!G13,"") | E9: =IF(AND(Gruppenphase!G13<>"",Gruppenphase!H13<>""),Gruppenphase!H13,"")
A10: 9 | B10: =IF(AND(Gruppenphase!G14<>"",Gruppenphase!H14<>""),Gruppenphase!E14,"") | C10: =IF(AND(Gruppenphase!G14<>"",Gruppenphase!H14<>""),Gruppenphase!F14,"") | D10: =IF(AND(Gruppenphase!G14<>"",Gruppenphase!H14<>""),Gruppenphase!G14,"") | E10: =IF(AND(Gruppenphase!G14<>"",Gruppenphase!H14<>""),Gruppenphase!H14,"")
A11: 10 | B11: =IF(AND(Gruppenphase!G15<>"",Gruppenphase!H15<>""),Gruppenphase!E15,"") | C11: =IF(AND(Gruppenphase!G15<>"",Gruppenphase!H15<>""),Gruppenphase!F15,"") | D11: =IF(AND(Gruppenphase!G15<>"",Gruppenphase!H15<>""),Gruppenphase!G15,"") | E11: =IF(AND(Gruppenphase!G15<>"",Gruppenphase!H15<>""),Gruppenphase!H15,"")
A12: 11 | B12: =IF(AND(Gruppenphase!M6<>"",Gruppenphase!N6<>""),Gruppenphase!K6,"") | C12: =IF(AND(Gruppenphase!M6<>"",Gruppenphase!N6<>""),Gruppenphase!L6,"") | D12: =IF(AND(Gruppenphase!M6<>"",Gruppenphase!N6<>""),Gruppenphase!M6,"") | E12: =IF(AND(Gruppenphase!M6<>"",Gruppenphase!N6<>""),Gruppenphase!N6,"")
A13: 12 | B13: =IF(AND(Gruppenphase!M7<>"",Gruppenphase!N7<>""),Gruppenphase!K7,"") | C13: =IF(AND(Gruppenphase!M7<>"",Gruppenphase!N7<>""),Gruppenphase!L7,"") | D13: =IF(AND(Gruppenphase!M7<>"",Gruppenphase!N7<>""),Gruppenphase!M7,"") | E13: =IF(AND(Gruppenphase!M7<>"",Gruppenphase!N7<>""),Gruppenphase!N7,"")
A14: 13 | B14: =IF(AND(Gruppenphase!M8<>"",Gruppenphase!N8<>""),Gruppenphase!K8,"") | C14: =IF(AND(Gruppenphase!M8<>"",Gruppenphase!N8<>""),Gruppenphase!L8,"") | D14: =IF(AND(Gruppenphase!M8<>"",Gruppenphase!N8<>""),Gruppenphase!M8,"") | E14: =IF(AND(Gruppenphase!M8<>"",Gruppenphase!N8<>""),Gruppenphase!N8,"")
A15: 14 | B15: =IF(AND(Gruppenphase!M9<>"",Gruppenphase!N9<>""),Gruppenphase!K9,"") | C15: =IF(AND(Gruppenphase!M9<>"",Gruppenphase!N9<>""),Gruppenphase!L9,"") | D15: =IF(AND(Gruppenphase!M9<>"",Gruppenphase!N9<>""),Gruppenphase!M9,"") | E15: =IF(AND(Gruppenphase!M9<>"",Gruppenphase!N9<>""),Gruppenphase!N9,"")
A16: 15 | B16: =IF(AND(Gruppenphase!M10<>"",Gruppenphase!N10<>""),Gruppenphase!K10,"") | C16: =IF(AND(Gruppenphase!M10<>"",Gruppenphase!N10<>""),Gruppenphase!L10,"") | D16: =IF(AND(Gruppenphase!M10<>"",Gruppenphase!N10<>""),Gruppenphase!M10,"") | E16: =IF(AND(Gruppenphase!M10<>"",Gruppenphase!N10<>""),Gruppenphase!N10,"")
A17: 16 | B17: =IF(AND(Gruppenphase!M11<>"",Gruppenphase!N11<>""),Gruppenphase!K11,"") | C17: =IF(AND(Gruppenphase!M11<>"",Gruppenphase!N11<>""),Gruppenphase!L11,"") | D17: =IF(AND(Gruppenphase!M11<>"",Gruppenphase!N11<>""),Gruppenphase!M11,"") | E17: =IF(AND(Gruppenphase!M11<>"",Gruppenphase!N11<>""),Gruppenphase!N11,"")
A18: 17 | B18: =IF(AND(Gruppenphase!M12<>"",Gruppenphase!N12<>""),Gruppenphase!K12,"") | C18: =IF(AND(Gruppenphase!M12<>"",Gruppenphase!N12<>""),Gruppenphase!L12,"") | D18: =IF(AND(Gruppenphase!M12<>"",Gruppenphase!N12<>""),Gruppenphase!M12,"") | E18: =IF(AND(Gruppenphase!M12<>"",Gruppenphase!N12<>""),Gruppenphase!N12,"")
A19: 18 | B19: =IF(AND(Gruppenphase!M13<>"",Gruppenphase!N13<>""),Gruppenphase!K13,"") | C19: =IF(AND(Gruppenphase!M13<>"",Gruppenphase!N13<>""),Gruppenphase!L13,"") | D19: =IF(AND(Gruppenphase!M13<>"",Gruppenphase!N13<>""),Gruppenphase!M13,"") | E19: =IF(AND(Gruppenphase!M13<>"",Gruppenphase!N13<>""),Gruppenphase!N13,"")
A20: 19 | B20: =IF(AND(Gruppenphase!M14<>"",Gruppenphase!N14<>""),Gruppenphase!K14,"") | C20: =IF(AND(Gruppenphase!M14<>"",Gruppenphase!N14<>""),Gruppenphase!L14,"") | D20: =IF(AND(Gruppenphase!M14<>"",Gruppenphase!N14<>""),Gruppenphase!M14,"") | E20: =IF(AND(Gruppenphase!M14<>"",Gruppenphase!N14<>""),Gruppenphase!N14,"")
A21: 20 | B21: =IF(AND(Gruppenphase!M15<>"",Gruppenphase!N15<>""),Gruppenphase!K15,"") | C21: =IF(AND(Gruppenphase!M15<>"",Gruppenphase!N15<>""),Gruppenphase!L15,"") | D21: =IF(AND(Gruppenphase!M15<>"",Gruppenphase!N15<>""),Gruppenphase!M15,"") | E21: =IF(AND(Gruppenphase!M15<>"",Gruppenphase!N15<>""),Gruppenphase!N15,"")
A22: 21 | B22: =IF(AND(Gruppenphase!G18<>"",Gruppenphase!H18<>""),Gruppenphase!E18,"") | C22: =IF(AND(Gruppenphase!G18<>"",Gruppenphase!H18<>""),Gruppenphase!F18,"") | D22: =IF(AND(Gruppenphase!G18<>"",Gruppenphase!H18<>""),Gruppenphase!G18,"") | E22: =IF(AND(Gruppenphase!G18<>"",Gruppenphase!H18<>""),Gruppenphase!H18,"")
A23: 22 | B23: =IF(AND(Gruppenphase!G19<>"",Gruppenphase!H19<>""),Gruppenphase!E19,"") | C23: =IF(AND(Gruppenphase!G19<>"",Gruppenphase!H19<>""),Gruppenphase!F19,"") | D23: =IF(AND(Gruppenphase!G19<>"",Gruppenphase!H19<>""),Gruppenphase!G19,"") | E23: =IF(AND(Gruppenphase!G19<>"",Gruppenphase!H19<>""),Gruppenphase!H19,"")
A24: 23 | B24: =IF(AND(Gruppenphase!G20<>"",Gruppenphase!H20<>""),Gruppenphase!E20,"") | C24: =IF(AND(Gruppenphase!G20<>"",Gruppenphase!H20<>""),Gruppenphase!F20,"") | D24: =IF(AND(Gruppenphase!G20<>"",Gruppenphase!H20<>""),Gruppenphase!G20,"") | E24: =IF(AND(Gruppenphase!G20<>"",Gruppenphase!H20<>""),Gruppenphase!H20,"")
A25: 24 | B25: =IF(AND(Gruppenphase!G21<>"",Gruppenphase!H21<>""),Gruppenphase!E21,"") | C25: =IF(AND(Gruppenphase!G21<>"",Gruppenphase!H21<>""),Gruppenphase!F21,"") | D25: =IF(AND(Gruppenphase!G21<>"",Gruppenphase!H21<>""),Gruppenphase!G21,"") | E25: =IF(AND(Gruppenphase!G21<>"",Gruppenphase!H21<>""),Gruppenphase!H21,"")
A26: 25 | B26: =IF(AND(Gruppenphase!G22<>"",Gruppenphase!H22<>""),Gruppenphase!E22,"") | C26: =IF(AND(Gruppenphase!G22<>"",Gruppenphase!H22<>""),Gruppenphase!F22,"") | D26: =IF(AND(Gruppenphase!G22<>"",Gruppenphase!H22<>""),Gruppenphase!G22,"") | E26: =IF(AND(Gruppenphase!G22<>"",Gruppenphase!H22<>""),Gruppenphase!H22,"")
A27: 26 | B27: =IF(AND(Gruppenphase!G23<>"",Gruppenphase!H23<>""),Gruppenphase!E23,"") | C27: =IF(AND(Gruppenphase!G23<>"",Gruppenphase!H23<>""),Gruppenphase!F23,"") | D27: =IF(AND(Gruppenphase!G23<>"",Gruppenphase!H23<>""),Gruppenphase!G23,"") | E27: =IF(AND(Gruppenphase!G23<>"",Gruppenphase!H23<>""),Gruppenphase!H23,"")
A28: 27 | B28: =IF(AND(Gruppenphase!G24<>"",Gruppenphase!H24<>""),Gruppenphase!E24,"") | C28: =IF(AND(Gruppenphase!G24<>"",Gruppenphase!H24<>""),Gruppenphase!F24,"") | D28: =IF(AND(Gruppenphase!G24<>"",Gruppenphase!H24<>""),Gruppenphase!G24,"") | E28: =IF(AND(Gruppenphase!G24<>"",Gruppenphase!H24<>""),Gruppenphase!H24,"")
A29: 28 | B29: =IF(AND(Gruppenphase!G25<>"",Gruppenphase!H25<>""),Gruppenphase!E25,"") | C29: =IF(AND(Gruppenphase!G25<>"",Gruppenphase!H25<>""),Gruppenphase!F25,"") | D29: =IF(AND(Gruppenphase!G25<>"",Gruppenphase!H25<>""),Gruppenphase!G25,"") | E29: =IF(AND(Gruppenphase!G25<>"",Gruppenphase!H25<>""),Gruppenphase!H25,"")
A30: 29 | B30: =IF(AND(Gruppenphase!G26<>"",Gruppenphase!H26<>""),Gruppenphase!E26,"") | C30: =IF(AND(Gruppenphase!G26<>"",Gruppenphase!H26<>""),Gruppenphase!F26,"") | D30: =IF(AND(Gruppenphase!G26<>"",Gruppenphase!H26<>""),Gruppenphase!G26,"") | E30: =IF(AND(Gruppenphase!G26<>"",Gruppenphase!H26<>""),Gruppenphase!H26,"")
A31: 30 | B31: =IF(AND(Gruppenphase!G27<>"",Gruppenphase!H27<>""),Gruppenphase!E27,"") | C31: =IF(AND(Gruppenphase!G27<>"",Gruppenphase!H27<>""),Gruppenphase!F27,"") | D31: =IF(AND(Gruppenphase!G27<>"",Gruppenphase!H27<>""),Gruppenphase!G27,"") | E31: =IF(AND(Gruppenphase!G27<>"",Gruppenphase!H27<>""),Gruppenphase!H27,"")
A32: 31 | B32: =IF(AND(Gruppenphase!M18<>"",Gruppenphase!N18<>""),Gruppenphase!K18,"") | C32: =IF(AND(Gruppenphase!M18<>"",Gruppenphase!N18<>""),Gruppenphase!L18,"") | D32: =IF(AND(Gruppenphase!M18<>"",Gruppenphase!N18<>""),Gruppenphase!M18,"") | E32: =IF(AND(Gruppenphase!M18<>"",Gruppenphase!N18<>""),Gruppenphase!N18,"")
A33: 32 | B33: =IF(AND(Gruppenphase!M19<>"",Gruppenphase!N19<>""),Gruppenphase!K19,"") | C33: =IF(AND(Gruppenphase!M19<>"",Gruppenphase!N19<>""),Gruppenphase!L19,"") | D33: =IF(AND(Gruppenphase!M19<>"",Gruppenphase!N19<>""),Gruppenphase!M19,"") | E33: =IF(AND(Gruppenphase!M19<>"",Gruppenphase!N19<>""),Gruppenphase!N19,"")
A34: 33 | B34: =IF(AND(Gruppenphase!M20<>"",Gruppenphase!N20<>""),Gruppenphase!K20,"") | C34: =IF(AND(Gruppenphase!M20<>"",Gruppenphase!N20<>""),Gruppenphase!L20,"") | D34: =IF(AND(Gruppenphase!M20<>"",Gruppenphase!N20<>""),Gruppenphase!M20,"") | E34: =IF(AND(Gruppenphase!M20<>"",Gruppenphase!N20<>""),Gruppenphase!N20,"")
A35: 34 | B35: =IF(AND(Gruppenphase!M21<>"",Gruppenphase!N21<>""),Gruppenphase!K21,"") | C35: =IF(AND(Gruppenphase!M21<>"",Gruppenphase!N21<>""),Gruppenphase!L21,"") | D35: =IF(AND(Gruppenphase!M21<>"",Gruppenphase!N21<>""),Gruppenphase!M21,"") | E35: =IF(AND(Gruppenphase!M21<>"",Gruppenphase!N21<>""),Gruppenphase!N21,"")
A36: 35 | B36: =IF(AND(Gruppenphase!M22<>"",Gruppenphase!N22<>""),Gruppenphase!K22,"") | C36: =IF(AND(Gruppenphase!M22<>"",Gruppenphase!N22<>""),Gruppenphase!L22,"") | D36: =IF(AND(Gruppenphase!M22<>"",Gruppenphase!N22<>""),Gruppenphase!M22,"") | E36: =IF(AND(Gruppenphase!M22<>"",Gruppenphase!N22<>""),Gruppenphase!N22,"")
A37: 36 | B37: =IF(AND(Gruppenphase!M23<>"",Gruppenphase!N23<>""),Gruppenphase!K23,"") | C37: =IF(AND(Gruppenphase!M23<>"",Gruppenphase!N23<>""),Gruppenphase!L23,"") | D37: =IF(AND(Gruppenphase!M23<>"",Gruppenphase!N23<>""),Gruppenphase!M23,"") | E37: =IF(AND(Gruppenphase!M23<>"",Gruppenphase!N23<>""),Gruppenphase!N23,"")
A38: 37 | B38: =IF(AND(Gruppenphase!M24<>"",Gruppenphase!N24<>""),Gruppenphase!K24,"") | C38: =IF(AND(Gruppenphase!M24<>"",Gruppenphase!N24<>""),Gruppenphase!L24,"") | D38: =IF(AND(Gruppenphase!M24<>"",Gruppenphase!N24<>""),Gruppenphase!M24,"") | E38: =IF(AND(Gruppenphase!M24<>"",Gruppenphase!N24<>""),Gruppenphase!N24,"")
A39: 38 | B39: =IF(AND(Gruppenphase!M25<>"",Gruppenphase!N25<>""),Gruppenphase!K25,"") | C39: =IF(AND(Gruppenphase!M25<>"",Gruppenphase!N25<>""),Gruppenphase!L25,"") | D39: =IF(AND(Gruppenphase!M25<>"",Gruppenphase!N25<>""),Gruppenphase!M25,"") | E39: =IF(AND(Gruppenphase!M25<>"",Gruppenphase!N25<>""),Gruppenphase!N25,"")
A40: 39 | B40: =IF(AND(Gruppenphase!M26<>"",Gruppenphase!N26<>""),Gruppenphase!K26,"") | C40: =IF(AND(Gruppenphase!M26<>"",Gruppenphase!N26<>""),Gruppenphase!L26,"") | D40: =IF(AND(Gruppenphase!M26<>"",Gruppenphase!N26<>""),Gruppenphase!M26,"") | E40: =IF(AND(Gruppenphase!M26<>"",Gruppenphase!N26<>""),Gruppenphase!N26,"")
...
