Workbook

Sheet Gruppenphase
D4: Spiele Gruppenphase
C5: Platz 1 | D5: Zeit | E5: Gruppe A | G5: Tore | J5: Zeit | K5: Gruppe B | M5: Tore
D6: 0.34722222 | E6: 1BHME | F6: 3AHITN | G6: 5 | H6: 3 | J6: 0.35555556 | K6: 2AHEL | L6: 1AHEL | M6: 1 | N6: 2
D7: 0.36388889 | E7: 3AHMBZ | F7: 3BHMBZ | G7: 3 | H7: 2 | J7: 0.37222222 | K7: 2AHMBZ | L7: 3AHEL | M7: 6 | N7: 1
D8: 0.38055556 | E8: 4AHMBZ | F8: 1BHME | G8: 3 | H8: 2 | J8: 0.38888889 | K8: 2AHME | L8: 2AHEL
D9: 0.39722222 | E9: 3AHITN | F9: 3AHMBZ | J9: 0.40555556 | K9: 1AHEL | L9: 2AHMBZ
D10: 0.41388889 | E10: 3BHMBZ | F10: 4AHMBZ | J10: 0.42222222 | K10: 3AHEL | L10: 2AHME
D11: 0.43055556 | E11: 1BHME | F11: 3AHMBZ | J11: 0.43888889 | K11: 2AHEL | L11: 2AHMBZ
D12: 0.44722222 | E12: 3AHITN | F12: 3BHMBZ | J12: 0.45555556 | K12: 1AHEL | L12: 3AHEL
D13: 0.46388889 | E13: 3AHMBZ | F13: 4AHMBZ | J13: 0.47222222 | K13: 2AHMBZ | L13: 2AHME
D14: 0.48055556 | E14: 1BHME | F14: 3BHMBZ | J14: 0.48888889 | K14: 2AHEL | L14: 3AHEL
D15: 0.49722222 | E15: 3AHITN | F15: 4AHMBZ | J15: 0.50555556 | K15: 1AHEL | L15: 2AHME
E16: Strandseite | F16: Laufbahnseite | K16: Strandseite | L16: Laufbahnseite
C17: Platz 2 | D17: Zeit | E17: Gruppe C | G17: Tore | J17: Zeit | K17: Gruppe D | M17: Tore
D18: 0.34722222 | E18: 1AHMBZ | F18: 2AHITN | G18: 4 | H18: 1 | J18: 0.35555556 | K18: 2AFMBZ | L18: 4BHME | M18: 3 | N18: 4
D19: 0.36388889 | E19: 1AHITN | F19: 2BHME | G19: 4 | H19: 1 | J19: 0.37222222 | K19: 3BHME | L19: 4AHEL | M19: 1 | N19: 1
D20: 0.38055556 | E20: 1AHME | F20: 2AHITN | J20: 0.38888889 | K20: 4BHME | L20: 4AHITN
D21: 0.39722222 | E21: 1AHMBZ | F21: 1AHITN | J21: 0.40555556 | K21: 2AFMBZ | L21: 3BHME
D22: 0.41388889 | E22: 2BHME | F22: 1AHME | J22: 0.42222222 | K22: 4AHEL | L22: 4AHITN
D23: 0.43055556 | E23: 2AHITN | F23: 1AHITN | J23: 0.43888889 | K23: 3BHME | L23: 4BHME
D24: 0.44722222 | E24: 1AHMBZ | F24: 2BHME | J24: 0.45555556 | K24: 2AFMBZ | L24: 4AHEL
D25: 0.46388889 | E25: 1AHITN | F25: 1AHME | J25: 0.47222222 | K25: 3BHME | L25: 4AHITN
D26: 0.48055556 | E26: 2AHITN | F26: 2BHME | J26: 0.48888889 | K26: 4BHME | L26: 4AHEL
D27: 0.49722222 | E27: 1AHMBZ | F27: 1AHME | J27: 0.50555556 | K27: 2AFMBZ | L27: 4AHITN
E28: Strandseite | F28: Laufbahnseite | K28: Strandseite | L28: Laufbahnseite

Sheet Spiele
A1: Spiel | B1: Team A | C1: Team B | D1: Tore A | E1: Tore B | H1: idx | I1: Team A | J1: Team B | K1: Tore A | L1: Tore B | M1: sort (Quelle: Gruppenphase – nicht aendern)
A2: =IF(B2="","",ROW()-1) -> 1 | B2: =IFERROR(INDEX($I$2:$I$41,MATCH(SMALL($M$2:$M$41,ROW()-1),$H$2:$H$41,0)),"") -> 1BHME | C2: =IFERROR(INDEX($J$2:$J$41,MATCH(SMALL($M$2:$M$41,ROW()-1),$H$2:$H$41,0)),"") -> 3AHITN | D2: =IFERROR(INDEX($K$2:$K$41,MATCH(SMALL($M$2:$M$41,ROW()-1),$H$2:$H$41,0)),"") -> 5 | E2: =IFERROR(INDEX($L$2:$L$41,MATCH(SMALL($M$2:$M$41,ROW()-1),$H$2:$H$41,0)),"") -> 3 | H2: 1 | I2: =Gruppenphase!E6 -> 1BHME | J2: =Gruppenphase!F6 -> 3AHITN | K2: =IF(Gruppenphase!G6="","",Gruppenphase!G6) -> 5 | L2: =IF(Gruppenphase!H6="","",Gruppenphase!H6) -> 3 | M2: =IF(AND(K2<>"",L2<>""),H2,9999) -> 1
A3: =IF(B3="","",ROW()-1) -> 2 | B3: =IFERROR(INDEX($I$2:$I$41,MATCH(SMALL($M$2:$M$41,ROW()-1),$H$2:$H$41,0)),"") -> 3AHMBZ | C3: =IFERROR(INDEX($J$2:$J$41,MATCH(SMALL($M$2:$M$41,ROW()-1),$H$2:$H$41,0)),"") -> 3BHMBZ | D3: =IFERROR(INDEX($K$2:$K$41,MATCH(SMALL($M$2:$M$41,ROW()-1),$H$2:$H$41,0)),"") -> 3 | E3: =IFERROR(INDEX($L$2:$L$41,MATCH(SMALL($M$2:$M$41,ROW()-1),$H$2:$H$41,0)),"") -> 2 | H3: 2 | I3: =Gruppenphase!E7 -> 3AHMBZ | J3: =Gruppenphase!F7 -> 3BHMBZ | K3: =IF(Gruppenphase!G7="","",Gruppenphase!G7) -> 3 | L3: =IF(Gruppenphase!H7="","",Gruppenphase!H7) -> 2 | M3: =IF(AND(K3<>"",L3<>""),H3,9999) -> 2
A4: =IF(B4="","",ROW()-1) -> 3 | B4: =IFERROR(INDEX($I$2:$I$41,MATCH(SMALL($M$2:$M$41,ROW()-1),$H$2:$H$41,0)),"") -> 4AHMBZ | C4: =IFERROR(INDEX($J$2:$J$41,MATCH(SMALL($M$2:$M$41,ROW()-1),$H$2:$H$41,0)),"") -> 1BHME | D4: =IFERROR(INDEX($K$2:$K$41,MATCH(SMALL($M$2:$M$41,ROW()-1),$H$2:$H$41,0)),"") -> 3 | E4: =IFERROR(INDEX($L$2:$L$41,MATCH(SMALL($M$2:$M$41,ROW()-1),$H$2:$H$41,0)),"") -> 2 | H4: 3 | I4: =Gruppenphase!E8 -> 4AHMBZ | J4: =Gruppenphase!F8 -> 1BHME | K4: =IF(Gruppenphase!G8="","",Gruppenphase!G8) -> 3 | L4: =IF(Gruppenphase!H8="","",Gruppenphase!H8) -> 2 | M4: =IF(AND(K4<>"",L4<>""),H4,9999) -> 3
A5: =IF(B5="","",ROW()-1) -> 4 | B5: =IFERROR(INDEX($I$2:$I$41,MATCH(SMALL($M$2:$M$41,ROW()-1),$H$2:$H$41,0)),"") -> 2AHEL | C5: =IFERROR(INDEX($J$2:$J$41,MATCH(SMALL($M$2:$M$41,ROW()-1),$H$2:$H$41,0)),"") -> 1AHEL | D5: =IFERROR(INDEX($K$2:$K$41,MATCH(SMALL($M$2:$M$41,ROW()-1),$H$2:$H$41,0)),"") -> 1 | E5: =IFERROR(INDEX($L$2:$L$41,MATCH(SMALL($M$2:$M$41,ROW()-1),$H$2:$H$41,0)),"") -> 2 | H5: 4 | I5: =Gruppenphase!E9 -> 3AHITN | J5: =Gruppenphase!F9 -> 3AHMBZ | K5: =IF(Gruppenphase!G9="","",Gruppenphase!G9) | L5: =IF(Gruppenphase!H9="","",Gruppenphase!H9) | M5: =IF(AND(K5<>"",L5<>""),H5,9999) -> 9999
A6: =IF(B6="","",ROW()-1) -> 5 | B6: =IFERROR(INDEX($I$2:$I$41,MATCH(SMALL($M$2:$M$41,ROW()-1),$H$2:$H$41,0)),"") -> 2AHMBZ | C6: =IFERROR(INDEX($J$2:$J$41,MATCH(SMALL($M$2:$M$41,ROW()-1),$H$2:$H$41,0)),"") -> 3AHEL | D6: =IFERROR(INDEX($K$2:$K$41,MATCH(SMALL($M$2:$M$41,ROW()-1),$H$2:$H$41,0)),"") -> 6 | E6: =IFERROR(INDEX($L$2:$L$41,MATCH(SMALL($M$2:$M$41,ROW()-1),$H$2:$H$41,0)),"") -> 1 | H6: 5 | I6: =Gruppenphase!E10 -> 3BHMBZ | J6: =Gruppenphase!F10 -> 4AHMBZ | K6: =IF(Gruppenphase!G10="","",Gruppenphase!G10) | L6: =IF(Gruppenphase!H10="","",Gruppenphase!H10) | M6: =IF(AND(K6<>"",L6<>""),H6,9999) -> 9999
A7: =IF(B7="","",ROW()-1) -> 6 | B7: =IFERROR(INDEX($I$2:$I$41,MATCH(SMALL($M$2:$M$41,ROW()-1),$H$2:$H$41,0)),"") -> 1AHMBZ | C7: =IFERROR(INDEX($J$2:$J$41,MATCH(SMALL($M$2:$M$41,ROW()-1),$H$2:$H$41,0)),"") -> 2AHITN | D7: =IFERROR(INDEX($K$2:$K$41,MATCH(SMALL($M$2:$M$41,ROW()-1),$H$2:$H$41,0)),"") -> 4 | E7: =IFERROR(INDEX($L$2:$L$41,MATCH(SMALL($M$2:$M$41,ROW()-1),$H$2:$H$41,0)),"") -> 1 | H7: 6 | I7: =Gruppenphase!E11 -> 1BHME | J7: =Gruppenphase!F11 -> 3AHMBZ | K7: =IF(Gruppenphase!G11="","",Gruppenphase!G11) | L7: =IF(Gruppenphase!H11="","",Gruppenphase!H11) | M7: =IF(AND(K7<>"",L7<>""),H7,9999) -> 9999
A8: =IF(B8="","",ROW()-1) -> 7 | B8: =IFERROR(INDEX($I$2:$I$41,MATCH(SMALL($M$2:$M$41,ROW()-1),$H$2:$H$41,0)),"") -> 1AHITN | C8: =IFERROR(INDEX($J$2:$J$41,MATCH(SMALL($M$2:$M$41,ROW()-1),$H$2:$H$41,0)),"") -> 2BHME | D8: =IFERROR(INDEX($K$2:$K$41,MATCH(SMALL($M$2:$M$41,ROW()-1),$H$2:$H$41,0)),"") -> 4 | E8: =IFERROR(INDEX($L$2:$L$41,MATCH(SMALL($M$2:$M$41,ROW()-1),$H$2:$H$41,0)),"") -> 1 | H8: 7 | I8: =Gruppenphase!E12 -> 3AHITN | J8: =Gruppenphase!F12 -> 3BHMBZ | K8: =IF(Gruppenphase!G12="","",Gruppenphase!G12) | L8: =IF(Gruppenphase!H12="","",Gruppenphase!H12) | M8: =IF(AND(K8<>"",L8<>""),H8,9999) -> 9999
A9: =IF(B9="","",ROW()-1) -> 8 | B9: =IFERROR(INDEX($I$2:$I$41,MATCH(SMALL($M$2:$M$41,ROW()-1),$H$2:$H$41,0)),"") -> 2AFMBZ | C9: =IFERROR(INDEX($J$2:$J$41,MATCH(SMALL($M$2:$M$41,ROW()-1),$H$2:$H$41,0)),"") -> 4BHME | D9: =IFERROR(INDEX($K$2:$K$41,MATCH(SMALL($M$2:$M$41,ROW()-1),$H$2:$H$41,0)),"") -> 3 | E9: =IFERROR(INDEX($L$2:$L$41,MATCH(SMALL($M$2:$M$41,ROW()-1),$H$2:$H$41,0)),"") -> 4 | H9: 8 | I9: =Gruppenphase!E13 -> 3AHMBZ | J9: =Gruppenphase!F13 -> 4AHMBZ | K9: =IF(Gruppenphase!G13="","",Gruppenphase!G13) | L9: =IF(Gruppenphase!H13="","",Gruppenphase!H13) | M9: =IF(AND(K9<>"",L9<>""),H9,9999) -> 9999
A10: =IF(B10="","",ROW()-1) -> 9 | B10: =IFERROR(INDEX($I$2:$I$41,MATCH(SMALL($M$2:$M$41,ROW()-1),$H$2:$H$41,0)),"") -> 3BHME | C10: =IFERROR(INDEX($J$2:$J$41,MATCH(SMALL($M$2:$M$41,ROW()-1),$H$2:$H$41,0)),"") -> 4AHEL | D10: =IFERROR(INDEX($K$2:$K$41,MATCH(SMALL($M$2:$M$41,ROW()-1),$H$2:$H$41,0)),"") -> 1 | E10: =IFERROR(INDEX($L$2:$L$41,MATCH(SMALL($M$2:$M$41,ROW()-1),$H$2:$H$41,0)),"") -> 1 | H10: 9 | I10: =Gruppenphase!E14 -> 1BHME | J10: =Gruppenphase!F14 -> 3BHMBZ | K10: =IF(Gruppenphase!G14="","",Gruppenphase!G14) | L10: =IF(Gruppenphase!H14="","",Gruppenphase!H14) | M10: =IF(AND(K10<>"",L10<>""),H10,9999) -> 9999
A11: =IF(B11="","",ROW()-1) | B11: =IFERROR(INDEX($I$2:$I$41,MATCH(SMALL($M$2:$M$41,ROW()-1),$H$2:$H$41,0)),"") | C11: =IFERROR(INDEX($J$2:$J$41,MATCH(SMALL($M$2:$M$41,ROW()-1),$H$2:$H$41,0)),"") | D11: =IFERROR(INDEX($K$2:$K$41,MATCH(SMALL($M$2:$M$41,ROW()-1),$H$2:$H$41,0)),"") | E11: =IFERROR(INDEX($L$2:$L$41,MATCH(SMALL($M$2:$M$41,ROW()-1),$H$2:$H$41,0)),"") | H11: 10 | I11: =Gruppenphase!E15 -> 3AHITN | J11: =Gruppenphase!F15 -> 4AHMBZ | K11: =IF(Gruppenphase!G15="","",Gruppenphase!G15) | L11: =IF(Gruppenphase!H15="","",Gruppenphase!H15) | M11: =IF(AND(K11<>"",L11<>""),H11,9999) -> 9999
A12: =IF(B12="","",ROW()-1) | B12: =IFERROR(INDEX($I$2:$I$41,MATCH(SMALL($M$2:$M$41,ROW()-1),$H$2:$H$41,0)),"") | C12: =IFERROR(INDEX($J$2:$J$41,MATCH(SMALL($M$2:$M$41,ROW()-1),$H$2:$H$41,0)),"") | D12: =IFERROR(INDEX($K$2:$K$41,MATCH(SMALL($M$2:$M$41,ROW()-1),$H$2:$H$41,0)),"") | E12: =IFERROR(INDEX($L$2:$L$41,MATCH(SMALL($M$2:$M$41,ROW()-1),$H$2:$H$41,0)),"") | H12: 11 | I12: =Gruppenphase!K6 -> 2AHEL | J12: =Gruppenphase!L6 -> 1AHEL | K12: =IF(Gruppenphase!M6="","",Gruppenphase!M6) -> 1 | L12: =IF(Gruppenphase!N6="","",Gruppenphase!N6) -> 2 | M12: =IF(AND(K12<>"",L12<>""),H12,9999) -> 11
A13: =IF(B13="","",ROW()-1) | B13: =IFERROR(INDEX($I$2:$I$41,MATCH(SMALL($M$2:$M$41,ROW()-1),$H$2:$H$41,0)),"") | C13: =IFERROR(INDEX($J$2:$J$41,MATCH(SMALL($M$2:$M$41,ROW()-1),$H$2:$H$41,0)),"") | D13: =IFERROR(INDEX($K$2:$K$41,MATCH(SMALL($M$2:$M$41,ROW()-1),$H$2:$H$41,0)),"") | E13: =IFERROR(INDEX($L$2:$L$41,MATCH(SMALL($M$2:$M$41,ROW()-1),$H$2:$H$41,0)),"") | H13: 12 | I13: =Gruppenphase!K7 -> 2AHMBZ | J13: =Gruppenphase!L7 -> 3AHEL | K13: =IF(Gruppenphase!M7="","",Gruppenphase!M7) -> 6 | L13: =IF(Gruppenphase!N7="","",Gruppenphase!N7) -> 1 | M13: =IF(AND(K13<>"",L13<>""),H13,9999) -> 12
A14: =IF(B14="","",ROW()-1) | B14: =IFERROR(INDEX($I$2:$I$41,MATCH(SMALL($M$2:$M$41,ROW()-1),$H$2:$H$41,0)),"") | C14: =IFERROR(INDEX($J$2:$J$41,MATCH(SMALL($M$2:$M$41,ROW()-1),$H$2:$H$41,0)),"") | D14: =IFERROR(INDEX($K$2:$K$41,MATCH(SMALL($M$2:$M$41,ROW()-1),$H$2:$H$41,0)),"") | E14: =IFERROR(INDEX($L$2:$L$41,MATCH(SMALL($M$2:$M$41,ROW()-1),$H$2:$H$41,0)),"") | H14: 13 | I14: =Gruppenphase!K8 -> 2AHME | J14: =Gruppenphase!L8 -> 2AHEL | K14: =IF(Gruppenphase!M8="","",Gruppenphase!M8) | L14: =IF(Gruppenphase!N8="","",Gruppenphase!N8) | M14: =IF(AND(K14<>"",L14<>""),H14,9999) -> 9999
A15: =IF(B15="","",ROW()-1) | B15: =IFERROR(INDEX($I$2:$I$41,MATCH(SMALL($M$2:$M$41,ROW()-1),$H$2:$H$41,0)),"") | C15: =IFERROR(INDEX($J$2:$J$41,MATCH(SMALL($M$2:$M$41,ROW()-1),$H$2:$H$41,0)),"") | D15: =IFERROR(INDEX($K$2:$K$41,MATCH(SMALL($M$2:$M$41,ROW()-1),$H$2:$H$41,0)),"") | E15: =IFERROR(INDEX($L$2:$L$41,MATCH(SMALL($M$2:$M$41,ROW()-1),$H$2:$H$41,0)),"") | H15: 14 | I15: =Gruppenphase!K9 -> 1AHEL | J15: =Gruppenphase!L9 -> 2AHMBZ | K15: =IF(Gruppenphase!M9="","",Gruppenphase!M9) | L15: =IF(Gruppenphase!N9="","",Gruppenphase!N9) | M15: =IF(AND(K15<>"",L15<>""),H15,9999) -> 9999
A16: =IF(B16="","",ROW()-1) | B16: =IFERROR(INDEX($I$2:$I$41,MATCH(SMALL($M$2:$M$41,ROW()-1),$H$2:$H$41,0)),"") | C16: =IFERROR(INDEX($J$2:$J$41,MATCH(SMALL($M$2:$M$41,ROW()-1),$H$2:$H$41,0)),"") | D16: =IFERROR(INDEX($K$2:$K$41,MATCH(SMALL($M$2:$M$41,ROW()-1),$H$2:$H$41,0)),"") | E16: =IFERROR(INDEX($L$2:$L$41,MATCH(SMALL($M$2:$M$41,ROW()-1),$H$2:$H$41,0)),"") | H16: 15 | I16: =Gruppenphase!K10 -> 3AHEL | J16: =Gruppenphase!L10 -> 2AHME | K16: =IF(Gruppenphase!M10="","",Gruppenphase!M10) | L16: =IF(Gruppenphase!N10="","",Gruppenphase!N10) | M16: =IF(AND(K16<>"",L16<>""),H16,9999) -> 9999
A17: =IF(B17="","",ROW()-1) | B17: =IFERROR(INDEX($I$2:$I$41,MATCH(SMALL($M$2:$M$41,ROW()-1),$H$2:$H$41,0)),"") | C17: =IFERROR(INDEX($J$2:$J$41,MATCH(SMALL($M$2:$M$41,ROW()-1),$H$2:$H$41,0)),"") | D17: =IFERROR(INDEX($K$2:$K$41,MATCH(SMALL($M$2:$M$41,ROW()-1),$H$2:$H$41,0)),"") | E17: =IFERROR(INDEX($L$2:$L$41,MATCH(SMALL($M$2:$M$41,ROW()-1),$H$2:$H$41,0)),"") | H17: 16 | I17: =Gruppenphase!K11 -> 2AHEL | J17: =Gruppenphase!L11 -> 2AHMBZ | K17: =IF(Gruppenphase!M11="","",Gruppenphase!M11) | L17: =IF(Gruppenphase!N11="","",Gruppenphase!N11) | M17: =IF(AND(K17<>"",L17<>""),H17,9999) -> 9999
A18: =IF(B18="","",ROW()-1) | B18: =IFERROR(INDEX($I$2:$I$41,MATCH(SMALL($M$2:$M$41,ROW()-1),$H$2:$H$41,0)),"") | C18: =IFERROR(INDEX($J$2:$J$41,MATCH(SMALL($M$2:$M$41,ROW()-1),$H$2:$H$41,0)),"") | D18: =IFERROR(INDEX($K$2:$K$41,MATCH(SMALL($M$2:$M$41,ROW()-1),$H$2:$H$41,0)),"") | E18: =IFERROR(INDEX($L$2:$L$41,MATCH(SMALL($M$2:$M$41,ROW()-1),$H$2:$H$41,0)),"") | H18: 17 | I18: =Gruppenphase!K12 -> 1AHEL | J18: =Gruppenphase!L12 -> 3AHEL | K18: =IF(Gruppenphase!M12="","",Gruppenphase!M12) | L18: =IF(Gruppenphase!N12="","",Gruppenphase!N12) | M18: =IF(AND(K18<>"",L18<>""),H18,9999) -> 9999
A19: =IF(B19="","",ROW()-1) | B19: =IFERROR(INDEX($I$2:$I$41,MATCH(SMALL($M$2:$M$41,ROW()-1),$H$2:$H$41,0)),"") | C19: =IFERROR(INDEX($J$2:$J$41,MATCH(SMALL($M$2:$M$41,ROW()-1),$H$2:$H$41,0)),"") | D19: =IFERROR(INDEX($K$2:$K$41,MATCH(SMALL($M$2:$M$41,ROW()-1),$H$2:$H$41,0)),"") | E19: =IFERROR(INDEX($L$2:$L$41,MATCH(SMALL($M$2:$M$41,ROW()-1),$H$2:$H$41,0)),"") | H19: 18 | I19: =Gruppenphase!K13 -> 2AHMBZ | J19: =Gruppenphase!L13 -> 2AHME | K19: =IF(Gruppenphase!M13="","",Gruppenphase!M13) | L19: =IF(Gruppenphase!N13="","",Gruppenphase!N13) | M19: =IF(AND(K19<>"",L19<>""),H19,9999) -> 9999
A20: =IF(B20="","",ROW()-1) | B20: =IFERROR(INDEX($I$2:$I$41,MATCH(SMALL($M$2:$M$41,ROW()-1),$H$2:$H$41,0)),"") | C20: =IFERROR(INDEX($J$2:$J$41,MATCH(SMALL($M$2:$M$41,ROW()-1),$H$2:$H$41,0)),"") | D20: =IFERROR(INDEX($K$2:$K$41,MATCH(SMALL($M$2:$M$41,ROW()-1),$H$2:$H$41,0)),"") | E20: =IFERROR(INDEX($L$2:$L$41,MATCH(SMALL($M$2:$M$41,ROW()-1),$H$2:$H$41,0)),"") | H20: 19 | I20: =Gruppenphase!K14 -> 2AHEL | J20: =Gruppenphase!L14 -> 3AHEL | K20: =IF(Gruppenphase!M14="","",Gruppenphase!M14) | L20: =IF(Gruppenphase!N14="","",Gruppenphase!N14) | M20: =IF(AND(K20<>"",L20<>""),H20,9999) -> 9999
A21: =IF(B21="","",ROW()-1) | B21: =IFERROR(INDEX($I$2:$I$41,MATCH(SMALL($M$2:$M$41,ROW()-1),$H$2:$H$41,0)),"") | C21: =IFERROR(INDEX($J$2:$J$41,MATCH(SMALL($M$2:$M$41,ROW()-1),$H$2:$H$41,0)),"") | D21: =IFERROR(INDEX($K$2:$K$41,MATCH(SMALL($M$2:$M$41,ROW()-1),$H$2:$H$41,0)),"") | E21: =IFERROR(INDEX($L$2:$L$41,MATCH(SMALL($M$2:$M$41,ROW()-1),$H$2:$H$41,0)),"") | H21: 20 | I21: =Gruppenphase!K15 -> 1AHEL | J21: =Gruppenphase!L15 -> 2AHME | K21: =IF(Gruppenphase!M15="","",Gruppenphase!M15) | L21: =IF(Gruppenphase!N15="","",Gruppenphase!N15) | M21: =IF(AND(K21<>"",L21<>""),H21,9999) -> 9999
A22: =IF(B22="","",ROW()-1) | B22: =IFERROR(INDEX($I$2:$I$41,MATCH(SMALL($M$2:$M$41,ROW()-1),$H$2:$H$41,0)),"") | C22: =IFERROR(INDEX($J$2:$J$41,MATCH(SMALL($M$2:$M$41,ROW()-1),$H$2:$H$41,0)),"") | D22: =IFERROR(INDEX($K$2:$K$41,MATCH(SMALL($M$2:$M$41,ROW()-1),$H$2:$H$41,0)),"") | E22: =IFERROR(INDEX($L$2:$L$41,MATCH(SMALL($M$2:$M$41,ROW()-1),$H$2:$H$41,0)),"") | H22: 21 | I22: =Gruppenphase!E18 -> 1AHMBZ | J22: =Gruppenphase!F18 -> 2AHITN | K22: =IF(Gruppenphase!G18="","",Gruppenphase!G18) -> 4 | L22: =IF(Gruppenphase!H18="","",Gruppenphase!H18) -> 1 | M22: =IF(AND(K22<>"",L22<>""),H22,9999) -> 21
A23: =IF(B23="","",ROW()-1) | B23: =IFERROR(INDEX($I$2:$I$41,MATCH(SMALL($M$2:$M$41,ROW()-1),$H$2:$H$41,0)),"") | C23: =IFERROR(INDEX($J$2:$J$41,MATCH(SMALL($M$2:$M$41,ROW()-1),$H$2:$H$41,0)),"") | D23: =IFERROR(INDEX($K$2:$K$41,MATCH(SMALL($M$2:$M$41,ROW()-1),$H$2:$H$41,0)),"") | E23: =IFERROR(INDEX($L$2:$L$41,MATCH(SMALL($M$2:$M$41,ROW()-1),$H$2:$H$41,0)),"") | H23: 22 | I23: =Gruppenphase!E19 -> 1AHITN | J23: =Gruppenphase!F19 -> 2BHME | K23: =IF(Gruppenphase!G19="","",Gruppenphase!G19) -> 4 | L23: =IF(Gruppenphase!H19="","",Gruppenphase!H19) -> 1 | M23: =IF(AND(K23<>"",L23<>""),H23,9999) -> 22
A24: =IF(B24="","",ROW()-1) | B24: =IFERROR(INDEX($I$2:$I$41,MATCH(SMALL($M$2:$M$41,ROW()-1),$H$2:$H$41,0)),"") | C24: =IFERROR(INDEX($J$2:$J$41,MATCH(SMALL($M$2:$M$41,ROW()-1),$H$2:$H$41,0)),"") | D24: =IFERROR(INDEX($K$2:$K$41,MATCH(SMALL($M$2:$M$41,ROW()-1),$H$2:$H$41,0)),"") | E24: =IFERROR(INDEX($L$2:$L$41,MATCH(SMALL($M$2:$M$41,ROW()-1),$H$2:$H$41,0)),"") | H24: 23 | I24: =Gruppenphase!E20 -> 1AHME | J24: =Gruppenphase!F20 -> 2AHITN | K24: =IF(Gruppenphase!G20="","",Gruppenphase!G20) | L24: =IF(Gruppenphase!H20="","",Gruppenphase!H20) | M24: =IF(AND(K24<>"",L24<>""),H24,9999) -> 9999
A25: =IF(B25="","",ROW()-1) | B25: =IFERROR(INDEX($I$2:$I$41,MATCH(SMALL($M$2:$M$41,ROW()-1),$H$2:$H$41,0)),"") | C25: =IFERROR(INDEX($J$2:$J$41,MATCH(SMALL($M$2:$M$41,ROW()-1),$H$2:$H$41,0)),"") | D25: =IFERROR(INDEX($K$2:$K$41,MATCH(SMALL($M$2:$M$41,ROW()-1),$H$2:$H$41,0)),"") | E25: =IFERROR(INDEX($L$2:$L$41,MATCH(SMALL($M$2:$M$41,ROW()-1),$H$2:$H$41,0)),"") | H25: 24 | I25: =Gruppenphase!E21 -> 1AHMBZ | J25: =Gruppenphase!F21 -> 1AHITN | K25: =IF(Gruppenphase!G21="","",Gruppenphase!G21) | L25: =IF(Gruppenphase!H21="","",Gruppenphase!H21) | M25: =IF(AND(K25<>"",L25<>""),H25,9999) -> 9999
A26: =IF(B26="","",ROW()-1) | B26: =IFERROR(INDEX($I$2:$I$41,MATCH(SMALL($M$2:$M$41,ROW()-1),$H$2:$H$41,0)),"") | C26: =IFERROR(INDEX($J$2:$J$41,MATCH(SMALL($M$2:$M$41,ROW()-1),$H$2:$H$41,0)),"") | D26: =IFERROR(INDEX($K$2:$K$41,MATCH(SMALL($M$2:$M$41,ROW()-1),$H$2:$H$41,0)),"") | E26: =IFERROR(INDEX($L$2:$L$41,MATCH(SMALL($M$2:$M$41,ROW()-1),$H$2:$H$41,0)),"") | H26: 25 | I26: =Gruppenphase!E22 -> 2BHME | J26: =Gruppenphase!F22 -> 1AHME | K26: =IF(Gruppenphase!G22="","",Gruppenphase!G22) | L26: =IF(Gruppenphase!H22="","",Gruppenphase!H22) | M26: =IF(AND(K26<>"",L26<>""),H26,9999) -> 9999
A27: =IF(B27="","",ROW()-1) | B27: =IFERROR(INDEX($I$2:$I$41,MATCH(SMALL($M$2:$M$41,ROW()-1),$H$2:$H$41,0)),"") | C27: =IFERROR(INDEX($J$2:$J$41,MATCH(SMALL($M$2:$M$41,ROW()-1),$H$2:$H$41,0)),"") | D27: =IFERROR(INDEX($K$2:$K$41,MATCH(SMALL($M$2:$M$41,ROW()-1),$H$2:$H$41,0)),"") | E27: =IFERROR(INDEX($L$2:$L$41,MATCH(SMALL($M$2:$M$41,ROW()-1),$H$2:$H$41,0)),"") | H27: 26 | I27: =Gruppenphase!E23 -> 2AHITN | J27: =Gruppenphase!F23 -> 1AHITN | K27: =IF(Gruppenphase!G23="","",Gruppenphase!G23) | L27: =IF(Gruppenphase!H23="","",Gruppenphase!H23) | M27: =IF(AND(K27<>"",L27<>""),H27,9999) -> 9999
A28: =IF(B28="","",ROW()-1) | B28: =IFERROR(INDEX($I$2:$I$41,MATCH(SMALL($M$2:$M$41,ROW()-1),$H$2:$H$41,0)),"") | C28: =IFERROR(INDEX($J$2:$J$41,MATCH(SMALL($M$2:$M$41,ROW()-1),$H$2:$H$41,0)),"") | D28: =IFERROR(INDEX($K$2:$K$41,MATCH(SMALL($M$2:$M$41,ROW()-1),$H$2:$H$41,0)),"") | E28: =IFERROR(INDEX($L$2:$L$41,MATCH(SMALL($M$2:$M$41,ROW()-1),$H$2:$H$41,0)),"") | H28: 27 | I28: =Gruppenphase!E24 -> 1AHMBZ | J28: =Gruppenphase!F24 -> 2BHME | K28: =IF(Gruppenphase!G24="","",Gruppenphase!G24) | L28: =IF(Gruppenphase!H24="","",Gruppenphase!H24) | M28: =IF(AND(K28<>"",L28<>""),H28,9999) -> 9999
A29: =IF(B29="","",ROW()-1) | B29: =IFERROR(INDEX($I$2:$I$41,MATCH(SMALL($M$2:$M$41,ROW()-1),$H$2:$H$41,0)),"") | C29: =IFERROR(INDEX($J$2:$J$41,MATCH(SMALL($M$2:$M$41,ROW()-1),$H$2:$H$41,0)),"") | D29: =IFERROR(INDEX($K$2:$K$41,MATCH(SMALL($M$2:$M$41,ROW()-1),$H$2:$H$41,0)),"") | E29: =IFERROR(INDEX($L$2:$L$41,MATCH(SMALL($M$2:$M$41,ROW()-1),$H$2:$H$41,0)),"") | H29: 28 | I29: =Gruppenphase!E25 -> 1AHITN | J29: =Gruppenphase!F25 -> 1AHME | K29: =IF(Gruppenphase!G25="","",Gruppenphase!G25) | L29: =IF(Gruppenphase!H25="","",Gruppenphase!H25) | M29: =IF(AND(K29<>"",L29<>""),H29,9999) -> 9999
A30: =IF(B30="","",ROW()-1) | B30: =IFERROR(INDEX($I$2:$I$41,MATCH(SMALL($M$2:$M$41,ROW()-1),$H$2:$H$41,0)),"") | C30: =IFERROR(INDEX($J$2:$J$41,MATCH(SMALL($M$2:$M$41,ROW()-1),$H$2:$H$41,0)),"") | D30: =IFERROR(INDEX($K$2:$K$41,MATCH(SMALL($M$2:$M$41,ROW()-1),$H$2:$H$41,0)),"") | E30: =IFERROR(INDEX($L$2:$L$41,MATCH(SMALL($M$2:$M$41,ROW()-1),$H$2:$H$41,0)),"") | H30: 29 | I30: =Gruppenphase!E26 -> 2AHITN | J30: =Gruppenphase!F26 -> 2BHME | K30: =IF(Gruppenphase!G26="","",Gruppenphase!G26) | L30: =IF(Gruppenphase!H26="","",Gruppenphase!H26) | M30: =IF(AND(K30<>"",L30<>""),H30,9999) -> 9999
A31: =IF(B31="","",ROW()-1) | B31: =IFERROR(INDEX($I$2:$I$41,MATCH(SMALL($M$2:$M$41,ROW()-1),$H$2:$H$41,0)),"") | C31: =IFERROR(INDEX($J$2:$J$41,MATCH(SMALL($M$2:$M$41,ROW()-1),$H$2:$H$41,0)),"") | D31: =IFERROR(INDEX($K$2:$K$41,MATCH(SMALL($M$2:$M$41,ROW()-1),$H$2:$H$41,0)),"") | E31: =IFERROR(INDEX($L$2:$L$41,MATCH(SMALL($M$2:$M$41,ROW()-1),$H$2:$H$41,0)),"") | H31: 30 | I31: =Gruppenphase!E27 -> 1AHMBZ | J31: =Gruppenphase!F27 -> 1AHME | K31: =IF(Gruppenphase!G27="","",Gruppenphase!G27) | L31: =IF(Gruppenphase!H27="","",Gruppenphase!H27) | M31: =IF(AND(K31<>"",L31<>""),H31,9999) -> 9999
A32: =IF(B32="","",ROW()-1) | B32: =IFERROR(INDEX($I$2:$I$41,MATCH(SMALL($M$2:$M$41,ROW()-1),$H$2:$H$41,0)),"") | C32: =IFERROR(INDEX($J$2:$J$41,MATCH(SMALL($M$2:$M$41,ROW()-1),$H$2:$H$41,0)),"") | D32: =IFERROR(INDEX($K$2:$K$41,MATCH(SMALL($M$2:$M$41,ROW()-1),$H$2:$H$41,0)),"") | E32: =IFERROR(INDEX($L$2:$L$41,MATCH(SMALL($M$2:$M$41,ROW()-1),$H$2:$H$41,0)),"") | H32: 31 | I32: =Gruppenphase!K18 -> 2AFMBZ | J32: =Gruppenphase!L18 -> 4BHME | K32: =IF(Gruppenphase!M18="","",Gruppenphase!M18) -> 3 | L32: =IF(Gruppenphase!N18="","",Gruppenphase!N18) -> 4 | M32: =IF(AND(K32<>"",L32<>""),H32,9999) -> 31
A33: =IF(B33="","",ROW()-1) | B33: =IFERROR(INDEX($I$2:$I$41,MATCH(SMALL($M$2:$M$41,ROW()-1),$H$2:$H$41,0)),"") | C33: =IFERROR(INDEX($J$2:$J$41,MATCH(SMALL($M$2:$M$41,ROW()-1),$H$2:$H$41,0)),"") | D33: =IFERROR(INDEX($K$2:$K$41,MATCH(SMALL($M$2:$M$41,ROW()-1),$H$2:$H$41,0)),"") | E33: =IFERROR(INDEX($L$2:$L$41,MATCH(SMALL($M$2:$M$41,ROW()-1),$H$2:$H$41,0)),"") | H33: 32 | I33: =Gruppenphase!K19 -> 3BHME | J33: =Gruppenphase!L19 -> 4AHEL | K33: =IF(Gruppenphase!M19="","",Gruppenphase!M19) -> 1 | L33: =IF(Gruppenphase!N19="","",Gruppenphase!N19) -> 1 | M33: =IF(AND(K33<>"",L33<>""),H33,9999) -> 32
A34: =IF(B34="","",ROW()-1) | B34: =IFERROR(INDEX($I$2:$I$41,MATCH(SMALL($M$2:$M$41,ROW()-1),$H$2:$H$41,0)),"") | C34: =IFERROR(INDEX($J$2:$J$41,MATCH(SMALL($M$2:$M$41,ROW()-1),$H$2:$H$41,0)),"") | D34: =IFERROR(INDEX($K$2:$K$41,MATCH(SMALL($M$2:$M$41,ROW()-1),$H$2:$H$41,0)),"") | E34: =IFERROR(INDEX($L$2:$L$41,MATCH(SMALL($M$2:$M$41,ROW()-1),$H$2:$H$41,0)),"") | H34: 33 | I34: =Gruppenphase!K20 -> 4BHME | J34: =Gruppenphase!L20 -> 4AHITN | K34: =IF(Gruppenphase!M20="","",Gruppenphase!M20) | L34: =IF(Gruppenphase!N20="","",Gruppenphase!N20) | M34: =IF(AND(K34<>"",L34<>""),H34,9999) -> 9999
A35: =IF(B35="","",ROW()-1) | B35: =IFERROR(INDEX($I$2:$I$41,MATCH(SMALL($M$2:$M$41,ROW()-1),$H$2:$H$41,0)),"") | C35: =IFERROR(INDEX($J$2:$J$41,MATCH(SMALL($M$2:$M$41,ROW()-1),$H$2:$H$41,0)),"") | D35: =IFERROR(INDEX($K$2:$K$41,MATCH(SMALL($M$2:$M$41,ROW()-1),$H$2:$H$41,0)),"") | E35: =IFERROR(INDEX($L$2:$L$41,MATCH(SMALL($M$2:$M$41,ROW()-1),$H$2:$H$41,0)),"") | H35: 34 | I35: =Gruppenphase!K21 -> 2AFMBZ | J35: =Gruppenphase!L21 -> 3BHME | K35: =IF(Gruppenphase!M21="","",Gruppenphase!M21) | L35: =IF(Gruppenphase!N21="","",Gruppenphase!N21) | M35: =IF(AND(K35<>"",L35<>""),H35,9999) -> 9999
A36: =IF(B36="","",ROW()-1) | B36: =IFERROR(INDEX($I$2:$I$41,MATCH(SMALL($M$2:$M$41,ROW()-1),$H$2:$H$41,0)),"") | C36: =IFERROR(INDEX($J$2:$J$41,MATCH(SMALL($M$2:$M$41,ROW()-1),$H$2:$H$41,0)),"") | D36: =IFERROR(INDEX($K$2:$K$41,MATCH(SMALL($M$2:$M$41,ROW()-1),$H$2:$H$41,0)),"") | E36: =IFERROR(INDEX($L$2:$L$41,MATCH(SMALL($M$2:$M$41,ROW()-1),$H$2:$H$41,0)),"") | H36: 35 | I36: =Gruppenphase!K22 -> 4AHEL | J36: =Gruppenphase!L22 -> 4AHITN | K36: =IF(Gruppenphase!M22="","",Gruppenphase!M22) | L36: =IF(Gruppenphase!N22="","",Gruppenphase!N22) | M36: =IF(AND(K36<>"",L36<>""),H36,9999) -> 9999
A37: =IF(B37="","",ROW()-1) | B37: =IFERROR(INDEX($I$2:$I$41,MATCH(SMALL($M$2:$M$41,ROW()-1),$H$2:$H$41,0)),"") | C37: =IFERROR(INDEX($J$2:$J$41,MATCH(SMALL($M$2:$M$41,ROW()-1),$H$2:$H$41,0)),"") | D37: =IFERROR(INDEX($K$2:$K$41,MATCH(SMALL($M$2:$M$41,ROW()-1),$H$2:$H$41,0)),"") | E37: =IFERROR(INDEX($L$2:$L$41,MATCH(SMALL($M$2:$M$41,ROW()-1),$H$2:$H$41,0)),"") | H37: 36 | I37: =Gruppenphase!K23 -> 3BHME | J37: =Gruppenphase!L23 -> 4BHME | K37: =IF(Gruppenphase!M23="","",Gruppenphase!M23) | L37: =IF(Gruppenphase!N23="","",Gruppenphase!N23) | M37: =IF(AND(K37<>"",L37<>""),H37,9999) -> 9999
A38: =IF(B38="","",ROW()-1) | B38: =IFERROR(INDEX($I$2:$I$41,MATCH(SMALL($M$2:$M$41,ROW()-1),$H$2:$H$41,0)),"") | C38: =IFERROR(INDEX($J$2:$J$41,MATCH(SMALL($M$2:$M$41,ROW()-1),$H$2:$H$41,0)),"") | D38: =IFERROR(INDEX($K$2:$K$41,MATCH(SMALL($M$2:$M$41,ROW()-1),$H$2:$H$41,0)),"") | E38: =IFERROR(INDEX($L$2:$L$41,MATCH(SMALL($M$2:$M$41,ROW()-1),$H$2:$H$41,0)),"") | H38: 37 | I38: =Gruppenphase!K24 -> 2AFMBZ | J38: =Gruppenphase!L24 -> 4AHEL | K38: =IF(Gruppenphase!M24="","",Gruppenphase!M24) | L38: =IF(Gruppenphase!N24="","",Gruppenphase!N24) | M38: =IF(AND(K38<>"",L38<>""),H38,9999) -> 9999
A39: =IF(B39="","",ROW()-1) | B39: =IFERROR(INDEX($I$2:$I$41,MATCH(SMALL($M$2:$M$41,ROW()-1),$H$2:$H$41,0)),"") | C39: =IFERROR(INDEX($J$2:$J$41,MATCH(SMALL($M$2:$M$41,ROW()-1),$H$2:$H$41,0)),"") | D39: =IFERROR(INDEX($K$2:$K$41,MATCH(SMALL($M$2:$M$41,ROW()-1),$H$2:$H$41,0)),"") | E39: =IFERROR(INDEX($L$2:$L$41,MATCH(SMALL($M$2:$M$41,ROW()-1),$H$2:$H$41,0)),"") | H39: 38 | I39: =Gruppenphase!K25 -> 3BHME | J39: =Gruppenphase!L25 -> 4AHITN | K39: =IF(Gruppenphase!M25="","",Gruppenphase!M25) | L39: =IF(Gruppenphase!N25="","",Gruppenphase!N25) | M39: =IF(AND(K39<>"",L39<>""),H39,9999) -> 9999
A40: =IF(B40="","",ROW()-1) | B40: =IFERROR(INDEX($I$2:$I$41,MATCH(SMALL($M$2:$M$41,ROW()-1),$H$2:$H$41,0)),"") | C40: =IFERROR(INDEX($J$2:$J$41,MATCH(SMALL($M$2:$M$41,ROW()-1),$H$2:$H$41,0)),"") | D40: =IFERROR(INDEX($K$2:$K$41,MATCH(SMALL($M$2:$M$41,ROW()-1),$H$2:$H$41,0)),"") | E40: =IFERROR(INDEX($L$2:$L$41,MATCH(SMALL($M$2:$M$41,ROW()-1),$H$2:$H$41,0)),"") | H40: 39 | I40: =Gruppenphase!K26 -> 4BHME | J40: =Gruppenphase!L26 -> 4AHEL | K40: =IF(Gruppenphase!M26="","",Gruppenphase!M26) | L40: =IF(Gruppenphase!N26="","",Gruppenphase!N26) | M40: =IF(AND(K40<>"",L40<>""),H40,9999) -> 9999
...

Sheet Platzierung
A1: Team | B1: Spiele | C1: Siege | D1: Unentsch. | E1: Niederlagen | F1: Tore + | G1: Tore- | H1: Tordiff. | I1: Punkte | J1: Platzierung | M1: score (Hilfsspalte - nicht aendern)
A2: 1BHME | B2: =COUNTIF(Spiele!B:B,A2)+COUNTIF(Spiele!C:C,A2) -> 2 | C2: =SUMPRODUCT((Spiele!B$2:B$100=A2)*(Spiele!D$2:D$100>Spiele!E$2:E$100))+SUMPRODUCT((Spiele!C$2:C$100=A2)*(Spiele!E$2:E$100>Spiele!D$2:D$100)) -> 1 | D2: =SUMPRODUCT((Spiele!B$2:B$100=A2)*(Spiele!D$2:D$100=Spiele!E$2:E$100))+SUMPRODUCT((Spiele!C$2:C$100=A2)*(Spiele!D$2:D$100=Spiele!E$2:E$100)) -> 0 | E2: =B2-C2-D2 -> 1 | F2: =SUMIF(Spiele!B:B,A2,Spiele!D:D)+SUMIF(Spiele!C:C,A2,Spiele!E:E) -> 7 | G2: =SUMIF(Spiele!B:B,A2,Spiele!E:E)+SUMIF(Spiele!C:C,A2,Spiele!D:D) -> 6 | H2: =F2-G2 -> 1 | I2: =C2*3+D2 -> 3 | J2: =IF(B2=0,"",1+ROUND(SUMPRODUCT(($M$2:$M$6>M2)/COUNTIF($M$2:$M$6,$M$2:$M$6)),0)) -> 1 | K2: Gruppe A | M2: =IF(B2=0,-1000000000,I2*1000000+H2*1000+F2) -> 3001007
A3: 3AHITN | B3: =COUNTIF(Spiele!B:B,A3)+COUNTIF(Spiele!C:C,A3) -> 1 | C3: =SUMPRODUCT((Spiele!B$2:B$100=A3)*(Spiele!D$2:D$100>Spiele!E$2:E$100))+SUMPRODUCT((Spiele!C$2:C$100=A3)*(Spiele!E$2:E$100>Spiele!D$2:D$100)) -> 0 | D3: =SUMPRODUCT((Spiele!B$2:B$100=A3)*(Spiele!D$2:D$100=Spiele!E$2:E$100))+SUMPRODUCT((Spiele!C$2:C$100=A3)*(Spiele!D$2:D$100=Spiele!E$2:E$100)) -> 0 | E3: =B3-C3-D3 -> 1 | F3: =SUMIF(Spiele!B:B,A3,Spiele!D:D)+SUMIF(Spiele!C:C,A3,Spiele!E:E) -> 3 | G3: =SUMIF(Spiele!B:B,A3,Spiele!E:E)+SUMIF(Spiele!C:C,A3,Spiele!D:D) -> 5 | H3: =F3-G3 -> -2 | I3: =C3*3+D3 -> 0 | J3: =IF(B3=0,"",1+ROUND(SUMPRODUCT(($M$2:$M$6>M3)/COUNTIF($M$2:$M$6,$M$2:$M$6)),0)) -> 4 | M3: =IF(B3=0,-1000000000,I3*1000000+H3*1000+F3) -> -1997
A4: 3AHMBZ | B4: =COUNTIF(Spiele!B:B,A4)+COUNTIF(Spiele!C:C,A4) -> 1 | C4: =SUMPRODUCT((Spiele!B$2:B$100=A4)*(Spiele!D$2:D$100>Spiele!E$2:E$100))+SUMPRODUCT((Spiele!C$2:C$100=A4)*(Spiele!E$2:E$100>Spiele!D$2:D$100)) -> 1 | D4: =SUMPRODUCT((Spiele!B$2:B$100=A4)*(Spiele!D$2:D$100=Spiele!E$2:E$100))+SUMPRODUCT((Spiele!C$2:C$100=A4)*(Spiele!D$2:D$100=Spiele!E$2:E$100)) -> 0 | E4: =B4-C4-D4 -> 0 | F4: =SUMIF(Spiele!B:B,A4,Spiele!D:D)+SUMIF(Spiele!C:C,A4,Spiele!E:E) -> 3 | G4: =SUMIF(Spiele!B:B,A4,Spiele!E:E)+SUMIF(Spiele!C:C,A4,Spiele!D:D) -> 2 | H4: =F4-G4 -> 1 | I4: =C4*3+D4 -> 3 | J4: =IF(B4=0,"",1+ROUND(SUMPRODUCT(($M$2:$M$6>M4)/COUNTIF($M$2:$M$6,$M$2:$M$6)),0)) -> 2 | M4: =IF(B4=0,-1000000000,I4*1000000+H4*1000+F4) -> 3001003
A5: 4AHMBZ | B5: =COUNTIF(Spiele!B:B,A5)+COUNTIF(Spiele!C:C,A5) -> 1 | C5: =SUMPRODUCT((Spiele!B$2:B$100=A5)*(Spiele!D$2:D$100>Spiele!E$2:E$100))+SUMPRODUCT((Spiele!C$2:C$100=A5)*(Spiele!E$2:E$100>Spiele!D$2:D$100)) -> 1 | D5: =SUMPRODUCT((Spiele!B$2:B$100=A5)*(Spiele!D$2:D$100=Spiele!E$2:E$100))+SUMPRODUCT((Spiele!C$2:C$100=A5)*(Spiele!D$2:D$100=Spiele!E$2:E$100)) -> 0 | E5: =B5-C5-D5 -> 0 | F5: =SUMIF(Spiele!B:B,A5,Spiele!D:D)+SUMIF(Spiele!C:C,A5,Spiele!E:E) -> 3 | G5: =SUMIF(Spiele!B:B,A5,Spiele!E:E)+SUMIF(Spiele!C:C,A5,Spiele!D:D) -> 2 | H5: =F5-G5 -> 1 | I5: =C5*3+D5 -> 3 | J5: =IF(B5=0,"",1+ROUND(SUMPRODUCT(($M$2:$M$6>M5)/COUNTIF($M$2:$M$6,$M$2:$M$6)),0)) -> 2 | M5: =IF(B5=0,-1000000000,I5*1000000+H5*1000+F5) -> 3001003
A6: 3BHMBZ | B6: =COUNTIF(Spiele!B:B,A6)+COUNTIF(Spiele!C:C,A6) -> 1 | C6: =SUMPRODUCT((Spiele!B$2:B$100=A6)*(Spiele!D$2:D$100>Spiele!E$2:E$100))+SUMPRODUCT((Spiele!C$2:C$100=A6)*(Spiele!E$2:E$100>Spiele!D$2:D$100)) -> 0 | D6: =SUMPRODUCT((Spiele!B$2:B$100=A6)*(Spiele!D$2:D$100=Spiele!E$2:E$100))+SUMPRODUCT((Spiele!C$2:C$100=A6)*(Spiele!D$2:D$100=Spiele!E$2:E$100)) -> 0 | E6: =B6-C6-D6 -> 1 | F6: =SUMIF(Spiele!B:B,A6,Spiele!D:D)+SUMIF(Spiele!C:C,A6,Spiele!E:E) -> 2 | G6: =SUMIF(Spiele!B:B,A6,Spiele!E:E)+SUMIF(Spiele!C:C,A6,Spiele!D:D) -> 3 | H6: =F6-G6 -> -1 | I6: =C6*3+D6 -> 0 | J6: =IF(B6=0,"",1+ROUND(SUMPRODUCT(($M$2:$M$6>M6)/COUNTIF($M$2:$M$6,$M$2:$M$6)),0)) -> 3 | M6: =IF(B6=0,-1000000000,I6*1000000+H6*1000+F6) -> -998
A7: 2AHEL | B7: =COUNTIF(Spiele!B:B,A7)+COUNTIF(Spiele!C:C,A7) -> 1 | C7: =SUMPRODUCT((Spiele!B$2:B$100=A7)*(Spiele!D$2:D$100>Spiele!E$2:E$100))+SUMPRODUCT((Spiele!C$2:C$100=A7)*(Spiele!E$2:E$100>Spiele!D$2:D$100)) -> 0 | D7: =SUMPRODUCT((Spiele!B$2:B$100=A7)*(Spiele!D$2:D$100=Spiele!E$2:E$100))+SUMPRODUCT((Spiele!C$2:C$100=A7)*(Spiele!D$2:D$100=Spiele!E$2:E$100)) -> 0 | E7: =B7-C7-D7 -> 1 | F7: =SUMIF(Spiele!B:B,A7,Spiele!D:D)+SUMIF(Spiele!C:C,A7,Spiele!E:E) -> 1 | G7: =SUMIF(Spiele!B:B,A7,Spiele!E:E)+SUMIF(Spiele!C:C,A7,Spiele!D:D) -> 2 | H7: =F7-G7 -> -1 | I7: =C7*3+D7 -> 0 | J7: =IF(B7=0,"",1+ROUND(SUMPRODUCT(($M$7:$M$11>M7)/COUNTIF($M$7:$M$11,$M$7:$M$11)),0)) -> 3 | K7: Gruppe B | M7: =IF(B7=0,-1000000000,I7*1000000+H7*1000+F7) -> -999
A8: 1AHEL | B8: =COUNTIF(Spiele!B:B,A8)+COUNTIF(Spiele!C:C,A8) -> 1 | C8: =SUMPRODUCT((Spiele!B$2:B$100=A8)*(Spiele!D$2:D$100>Spiele!E$2:E$100))+SUMPRODUCT((Spiele!C$2:C$100=A8)*(Spiele!E$2:E$100>Spiele!D$2:D$100)) -> 1 | D8: =SUMPRODUCT((Spiele!B$2:B$100=A8)*(Spiele!D$2:D$100=Spiele!E$2:E$100))+SUMPRODUCT((Spiele!C$2:C$100=A8)*(Spiele!D$2:D$100=Spiele!E$2:E$100)) -> 0 | E8: =B8-C8-D8 -> 0 | F8: =SUMIF(Spiele!B:B,A8,Spiele!D:D)+SUMIF(Spiele!C:C,A8,Spiele!E:E) -> 2 | G8: =SUMIF(Spiele!B:B,A8,Spiele!E:E)+SUMIF(Spiele!C:C,A8,Spiele!D:D) -> 1 | H8: =F8-G8 -> 1 | I8: =C8*3+D8 -> 3 | J8: =IF(B8=0,"",1+ROUND(SUMPRODUCT(($M$7:$M$11>M8)/COUNTIF($M$7:$M$11,$M$7:$M$11)),0)) -> 2 | M8: =IF(B8=0,-1000000000,I8*1000000+H8*1000+F8) -> 3001002
A9: 2AHMBZ | B9: =COUNTIF(Spiele!B:B,A9)+COUNTIF(Spiele!C:C,A9) -> 1 | C9: =SUMPRODUCT((Spiele!B$2:B$100=A9)*(Spiele!D$2:D$100>Spiele!E$2:E$100))+SUMPRODUCT((Spiele!C$2:C$100=A9)*(Spiele!E$2:E$100>Spiele!D$2:D$100)) -> 1 | D9: =SUMPRODUCT((Spiele!B$2:B$100=A9)*(Spiele!D$2:D$100=Spiele!E$2:E$100))+SUMPRODUCT((Spiele!C$2:C$100=A9)*(Spiele!D$2:D$100=Spiele!E$2:E$100)) -> 0 | E9: =B9-C9-D9 -> 0 | F9: =SUMIF(Spiele!B:B,A9,Spiele!D:D)+SUMIF(Spiele!C:C,A9,Spiele!E:E) -> 6 | G9: =SUMIF(Spiele!B:B,A9,Spiele!E:E)+SUMIF(Spiele!C:C,A9,Spiele!D:D) -> 1 | H9: =F9-G9 -> 5 | I9: =C9*3+D9 -> 3 | J9: =IF(B9=0,"",1+ROUND(SUMPRODUCT(($M$7:$M$11>M9)/COUNTIF($M$7:$M$11,$M$7:$M$11)),0)) -> 1 | M9: =IF(B9=0,-1000000000,I9*1000000+H9*1000+F9) -> 3005006
A10: 3AHEL | B10: =COUNTIF(Spiele!B:B,A10)+COUNTIF(Spiele!C:C,A10) -> 1 | C10: =SUMPRODUCT((Spiele!B$2:B$100=A10)*(Spiele!D$2:D$100>Spiele!E$2:E$100))+SUMPRODUCT((Spiele!C$2:C$100=A10)*(Spiele!E$2:E$100>Spiele!D$2:D$100)) -> 0 | D10: =SUMPRODUCT((Spiele!B$2:B$100=A10)*(Spiele!D$2:D$100=Spiele!E$2:E$100))+SUMPRODUCT((Spiele!C$2:C$100=A10)*(Spiele!D$2:D$100=Spiele!E$2:E$100)) -> 0 | E10: =B10-C10-D10 -> 1 | F10: =SUMIF(Spiele!B:B,A10,Spiele!D:D)+SUMIF(Spiele!C:C,A10,Spiele!E:E) -> 1 | G10: =SUMIF(Spiele!B:B,A10,Spiele!E:E)+SUMIF(Spiele!C:C,A10,Spiele!D:D) -> 6 | H10: =F10-G10 -> -5 | I10: =C10*3+D10 -> 0 | J10: =IF(B10=0,"",1+ROUND(SUMPRODUCT(($M$7:$M$11>M10)/COUNTIF($M$7:$M$11,$M$7:$M$11)),0)) -> 4 | M10: =IF(B10=0,-1000000000,I10*1000000+H10*1000+F10) -> -4999
A11: 2AHME | B11: =COUNTIF(Spiele!B:B,A11)+COUNTIF(Spiele!C:C,A11) -> 0 | C11: =SUMPRODUCT((Spiele!B$2:B$100=A11)*(Spiele!D$2:D$100>Spiele!E$2:E$100))+SUMPRODUCT((Spiele!C$2:C$100=A11)*(Spiele!E$2:E$100>Spiele!D$2:D$100)) -> 0 | D11: =SUMPRODUCT((Spiele!B$2:B$100=A11)*(Spiele!D$2:D$100=Spiele!E$2:E$100))+SUMPRODUCT((Spiele!C$2:C$100=A11)*(Spiele!D$2:D$100=Spiele!E$2:E$100)) -> 0 | E11: =B11-C11-D11 -> 0 | F11: =SUMIF(Spiele!B:B,A11,Spiele!D:D)+SUMIF(Spiele!C:C,A11,Spiele!E:E) -> 0 | G11: =SUMIF(Spiele!B:B,A11,Spiele!E:E)+SUMIF(Spiele!C:C,A11,Spiele!D:D) -> 0 | H11: =F11-G11 -> 0 | I11: =C11*3+D11 -> 0 | J11: =IF(B11=0,"",1+ROUND(SUMPRODUCT(($M$7:$M$11>M11)/COUNTIF($M$7:$M$11,$M$7:$M$11)),0)) | M11: =IF(B11=0,-1000000000,I11*1000000+H11*1000+F11) -> -1000000000
A12: 1AHMBZ | B12: =COUNTIF(Spiele!B:B,A12)+COUNTIF(Spiele!C:C,A12) -> 1 | C12: =SUMPRODUCT((Spiele!B$2:B$100=A12)*(Spiele!D$2:D$100>Spiele!E$2:E$100))+SUMPRODUCT((Spiele!C$2:C$100=A12)*(Spiele!E$2:E$100>Spiele!D$2:D$100)) -> 1 | D12: =SUMPRODUCT((Spiele!B$2:B$100=A12)*(Spiele!D$2:D$100=Spiele!E$2:E$100))+SUMPRODUCT((Spiele!C$2:C$100=A12)*(Spiele!D$2:D$100=Spiele!E$2:E$100)) -> 0 | E12: =B12-C12-D12 -> 0 | F12: =SUMIF(Spiele!B:B,A12,Spiele!D:D)+SUMIF(Spiele!C:C,A12,Spiele!E:E) -> 4 | G12: =SUMIF(Spiele!B:B,A12,Spiele!E:E)+SUMIF(Spiele!C:C,A12,Spiele!D:D) -> 1 | H12: =F12-G12 -> 3 | I12: =C12*3+D12 -> 3 | J12: =IF(B12=0,"",1+ROUND(SUMPRODUCT(($M$12:$M$16>M12)/COUNTIF($M$12:$M$16,$M$12:$M$16)),0)) -> 1 | K12: Gruppe C | M12: =IF(B12=0,-1000000000,I12*1000000+H12*1000+F12) -> 3003004
A13: 2AHITN | B13: =COUNTIF(Spiele!B:B,A13)+COUNTIF(Spiele!C:C,A13) -> 1 | C13: =SUMPRODUCT((Spiele!B$2:B$100=A13)*(Spiele!D$2:D$100>Spiele!E$2:E$100))+SUMPRODUCT((Spiele!C$2:C$100=A13)*(Spiele!E$2:E$100>Spiele!D$2:D$100)) -> 0 | D13: =SUMPRODUCT((Spiele!B$2:B$100=A13)*(Spiele!D$2:D$100=Spiele!E$2:E$100))+SUMPRODUCT((Spiele!C$2:C$100=A13)*(Spiele!D$2:D$100=Spiele!E$2:E$100)) -> 0 | E13: =B13-C13-D13 -> 1 | F13: =SUMIF(Spiele!B:B,A13,Spiele!D:D)+SUMIF(Spiele!C:C,A13,Spiele!E:E) -> 1 | G13: =SUMIF(Spiele!B:B,A13,Spiele!E:E)+SUMIF(Spiele!C:C,A13,Spiele!D:D) -> 4 | H13: =F13-G13 -> -3 | I13: =C13*3+D13 -> 0 | J13: =IF(B13=0,"",1+ROUND(SUMPRODUCT(($M$12:$M$16>M13)/COUNTIF($M$12:$M$16,$M$12:$M$16)),0)) -> 2 | M13: =IF(B13=0,-1000000000,I13*1000000+H13*1000+F13) -> -2999
A14: 1AHITN | B14: =COUNTIF(Spiele!B:B,A14)+COUNTIF(Spiele!C:C,A14) -> 1 | C14: =SUMPRODUCT((Spiele!B$2:B$100=A14)*(Spiele!D$2:D$100>Spiele!E$2:E$100))+SUMPRODUCT((Spiele!C$2:C$100=A14)*(Spiele!E$2:E$100>Spiele!D$2:D$100)) -> 1 | D14: =SUMPRODUCT((Spiele!B$2:B$100=A14)*(Spiele!D$2:D$100=Spiele!E$2:E$100))+SUMPRODUCT((Spiele!C$2:C$100=A14)*(Spiele!D$2:D$100=Spiele!E$2:E$100)) -> 0 | E14: =B14-C14-D14 -> 0 | F14: =SUMIF(Spiele!B:B,A14,Spiele!D:D)+SUMIF(Spiele!C:C,A14,Spiele!E:E) -> 4 | G14: =SUMIF(Spiele!B:B,A14,Spiele!E:E)+SUMIF(Spiele!C:C,A14,Spiele!D:D) -> 1 | H14: =F14-G14 -> 3 | I14: =C14*3+D14 -> 3 | J14: =IF(B14=0,"",1+ROUND(SUMPRODUCT(($M$12:$M$16>M14)/COUNTIF($M$12:$M$16,$M$12:$M$16)),0)) -> 1 | M14: =IF(B14=0,-1000000000,I14*1000000+H14*1000+F14) -> 3003004
A15: 2BHME | B15: =COUNTIF(Spiele!B:B,A15)+COUNTIF(Spiele!C:C,A15) -> 1 | C15: =SUMPRODUCT((Spiele!B$2:B$100=A15)*(Spiele!D$2:D$100>Spiele!E$2:E$100))+SUMPRODUCT((Spiele!C$2:C$100=A15)*(Spiele!E$2:E$100>Spiele!D$2:D$100)) -> 0 | D15: =SUMPRODUCT((Spiele!B$2:B$100=A15)*(Spiele!D$2:D$100=Spiele!E$2:E$100))+SUMPRODUCT((Spiele!C$2:C$100=A15)*(Spiele!D$2:D$100=Spiele!E$2:E$100)) -> 0 | E15: =B15-C15-D15 -> 1 | F15: =SUMIF(Spiele!B:B,A15,Spiele!D:D)+SUMIF(Spiele!C:C,A15,Spiele!E:E) -> 1 | G15: =SUMIF(Spiele!B:B,A15,Spiele!E:E)+SUMIF(Spiele!C:C,A15,Spiele!D:D) -> 4 | H15: =F15-G15 -> -3 | I15: =C15*3+D15 -> 0 | J15: =IF(B15=0,"",1+ROUND(SUMPRODUCT(($M$12:$M$16>M15)/COUNTIF($M$12:$M$16,$M$12:$M$16)),0)) -> 2 | M15: =IF(B15=0,-1000000000,I15*1000000+H15*1000+F15) -> -2999
A16: 1AHME | B16: =COUNTIF(Spiele!B:B,A16)+COUNTIF(Spiele!C:C,A16) -> 0 | C16: =SUMPRODUCT((Spiele!B$2:B$100=A16)*(Spiele!D$2:D$100>Spiele!E$2:E$100))+SUMPRODUCT((Spiele!C$2:C$100=A16)*(Spiele!E$2:E$100>Spiele!D$2:D$100)) -> 0 | D16: =SUMPRODUCT((Spiele!B$2:B$100=A16)*(Spiele!D$2:D$100=Spiele!E$2:E$100))+SUMPRODUCT((Spiele!C$2:C$100=A16)*(Spiele!D$2:D$100=Spiele!E$2:E$100)) -> 0 | E16: =B16-C16-D16 -> 0 | F16: =SUMIF(Spiele!B:B,A16,Spiele!D:D)+SUMIF(Spiele!C:C,A16,Spiele!E:E) -> 0 | G16: =SUMIF(Spiele!B:B,A16,Spiele!E:E)+SUMIF(Spiele!C:C,A16,Spiele!D:D) -> 0 | H16: =F16-G16 -> 0 | I16: =C16*3+D16 -> 0 | J16: =IF(B16=0,"",1+ROUND(SUMPRODUCT(($M$12:$M$16>M16)/COUNTIF($M$12:$M$16,$M$12:$M$16)),0)) | M16: =IF(B16=0,-1000000000,I16*1000000+H16*1000+F16) -> -1000000000
A17: 2AFMBZ | B17: =COUNTIF(Spiele!B:B,A17)+COUNTIF(Spiele!C:C,A17) -> 1 | C17: =SUMPRODUCT((Spiele!B$2:B$100=A17)*(Spiele!D$2:D$100>Spiele!E$2:E$100))+SUMPRODUCT((Spiele!C$2:C$100=A17)*(Spiele!E$2:E$100>Spiele!D$2:D$100)) -> 0 | D17: =SUMPRODUCT((Spiele!B$2:B$100=A17)*(Spiele!D$2:D$100=Spiele!E$2:E$100))+SUMPRODUCT((Spiele!C$2:C$100=A17)*(Spiele!D$2:D$100=Spiele!E$2:E$100)) -> 0 | E17: =B17-C17-D17 -> 1 | F17: =SUMIF(Spiele!B:B,A17,Spiele!D:D)+SUMIF(Spiele!C:C,A17,Spiele!E:E) -> 3 | G17: =SUMIF(Spiele!B:B,A17,Spiele!E:E)+SUMIF(Spiele!C:C,A17,Spiele!D:D) -> 4 | H17: =F17-G17 -> -1 | I17: =C17*3+D17 -> 0 | J17: =IF(B17=0,"",1+ROUND(SUMPRODUCT(($M$17:$M$21>M17)/COUNTIF($M$17:$M$21,$M$17:$M$21)),0)) -> 3 | K17: Gruppe D | M17: =IF(B17=0,-1000000000,I17*1000000+H17*1000+F17) -> -997
A18: 4BHME | B18: =COUNTIF(Spiele!B:B,A18)+COUNTIF(Spiele!C:C,A18) -> 1 | C18: =SUMPRODUCT((Spiele!B$2:B$100=A18)*(Spiele!D$2:D$100>Spiele!E$2:E$100))+SUMPRODUCT((Spiele!C$2:C$100=A18)*(Spiele!E$2:E$100>Spiele!D$2:D$100)) -> 1 | D18: =SUMPRODUCT((Spiele!B$2:B$100=A18)*(Spiele!D$2:D$100=Spiele!E$2:E$100))+SUMPRODUCT((Spiele!C$2:C$100=A18)*(Spiele!D$2:D$100=Spiele!E$2:E$100)) -> 0 | E18: =B18-C18-D18 -> 0 | F18: =SUMIF(Spiele!B:B,A18,Spiele!D:D)+SUMIF(Spiele!C:C,A18,Spiele!E:E) -> 4 | G18: =SUMIF(Spiele!B:B,A18,Spiele!E:E)+SUMIF(Spiele!C:C,A18,Spiele!D:D) -> 3 | H18: =F18-G18 -> 1 | I18: =C18*3+D18 -> 3 | J18: =IF(B18=0,"",1+ROUND(SUMPRODUCT(($M$17:$M$21>M18)/COUNTIF($M$17:$M$21,$M$17:$M$21)),0)) -> 1 | M18: =IF(B18=0,-1000000000,I18*1000000+H18*1000+F18) -> 3001004
A19: 3BHME | B19: =COUNTIF(Spiele!B:B,A19)+COUNTIF(Spiele!C:C,A19) -> 1 | C19: =SUMPRODUCT((Spiele!B$2:B$100=A19)*(Spiele!D$2:D$100>Spiele!E$2:E$100))+SUMPRODUCT((Spiele!C$2:C$100=A19)*(Spiele!E$2:E$100>Spiele!D$2:D$100)) -> 0 | D19: =SUMPRODUCT((Spiele!B$2:B$100=A19)*(Spiele!D$2:D$100=Spiele!E$2:E$100))+SUMPRODUCT((Spiele!C$2:C$100=A19)*(Spiele!D$2:D$100=Spiele!E$2:E$100)) -> 1 | E19: =B19-C19-D19 -> 0 | F19: =SUMIF(Spiele!B:B,A19,Spiele!D:D)+SUMIF(Spiele!C:C,A19,Spiele!E:E) -> 1 | G19: =SUMIF(Spiele!B:B,A19,Spiele!E:E)+SUMIF(Spiele!C:C,A19,Spiele!D:D) -> 1 | H19: =F19-G19 -> 0 | I19: =C19*3+D19 -> 1 | J19: =IF(B19=0,"",1+ROUND(SUMPRODUCT(($M$17:$M$21>M19)/COUNTIF($M$17:$M$21,$M$17:$M$21)),0)) -> 2 | M19: =IF(B19=0,-1000000000,I19*1000000+H19*1000+F19) -> 1000001
A20: 4AHEL | B20: =COUNTIF(Spiele!B:B,A20)+COUNTIF(Spiele!C:C,A20) -> 1 | C20: =SUMPRODUCT((Spiele!B$2:B$100=A20)*(Spiele!D$2:D$100>Spiele!E$2:E$100))+SUMPRODUCT((Spiele!C$2:C$100=A20)*(Spiele!E$2:E$100>Spiele!D$2:D$100)) -> 0 | D20: =SUMPRODUCT((Spiele!B$2:B$100=A20)*(Spiele!D$2:D$100=Spiele!E$2:E$100))+SUMPRODUCT((Spiele!C$2:C$100=A20)*(Spiele!D$2:D$100=Spiele!E$2:E$100)) -> 1 | E20: =B20-C20-D20 -> 0 | F20: =SUMIF(Spiele!B:B,A20,Spiele!D:D)+SUMIF(Spiele!C:C,A20,Spiele!E:E) -> 1 | G20: =SUMIF(Spiele!B:B,A20,Spiele!E:E)+SUMIF(Spiele!C:C,A20,Spiele!D:D) -> 1 | H20: =F20-G20 -> 0 | I20: =C20*3+D20 -> 1 | J20: =IF(B20=0,"",1+ROUND(SUMPRODUCT(($M$17:$M$21>M20)/COUNTIF($M$17:$M$21,$M$17:$M$21)),0)) -> 2 | M20: =IF(B20=0,-1000000000,I20*1000000+H20*1000+F20) -> 1000001
A21: 4AHITN | B21: =COUNTIF(Spiele!B:B,A21)+COUNTIF(Spiele!C:C,A21) -> 0 | C21: =SUMPRODUCT((Spiele!B$2:B$100=A21)*(Spiele!D$2:D$100>Spiele!E$2:E$100))+SUMPRODUCT((Spiele!C$2:C$100=A21)*(Spiele!E$2:E$100>Spiele!D$2:D$100)) -> 0 | D21: =SUMPRODUCT((Spiele!B$2:B$100=A21)*(Spiele!D$2:D$100=Spiele!E$2:E$100))+SUMPRODUCT((Spiele!C$2:C$100=A21)*(Spiele!D$2:D$100=Spiele!E$2:E$100)) -> 0 | E21: =B21-C21-D21 -> 0 | F21: =SUMIF(Spiele!B:B,A21,Spiele!D:D)+SUMIF(Spiele!C:C,A21,Spiele!E:E) -> 0 | G21: =SUMIF(Spiele!B:B,A21,Spiele!E:E)+SUMIF(Spiele!C:C,A21,Spiele!D:D) -> 0 | H21: =F21-G21 -> 0 | I21: =C21*3+D21 -> 0 | J21: =IF(B21=0,"",1+ROUND(SUMPRODUCT(($M$17:$M$21>M21)/COUNTIF($M$17:$M$21,$M$17:$M$21)),0)) | M21: =IF(B21=0,-1000000000,I21*1000000+H21*1000+F21) -> -1000000000

Sheet Kreuzspiele
B2: Kreuzspiele
B3: Platz 1 | H3: Platz 2
B4: Zeit | C4: Spiel | E4: Tore | H4: Zeit | I4: Spiel | K4: Tore
B5: 0.51736111 | H5: 0.51736111
B6: 0.52708333 | H6: 0.52708333
C7: Strandseite | D7: Laufbahnseite | I7: Strandseite | J7: Laufbahnseite
B9: Halbfinale
B10: Platz 1 | H10: Platz 2
B11: Zeit | C11: Spiel | E11: Tore | H11: Zeit | I11: Spiel | K11: Tore
B12: 0.53819444 | H12: 0.53819444
C13: Strandseite | D13: Laufbahnseite | I13: Strandseite | J13: Laufbahnseite
B15: Kleines Finale | H15: Finale
B16: Zeit | C16: Spiel | E16: Tore | H16: Zeit | I16: Spiel | K16: Tore
B17: 0.54861111 | H17: 0.55902778
C18: Strandseite | D18: Laufbahnseite | I18: Strandseite | J18: Laufbahnseite
